Workbook
Name HR: HR!$N$1
Name Monitoring: Monitoring!$A$1
Name SAP: 'SAP Report'!$A$1

Sheet Summary
B2: Board Approved vs Allotted
B3: (without Special Projects)
B4: SBU | C4: ORIGINAL BOARD APPROVED | D4: ADDITIONAL/ REDUCTION | E4: TOTAL BOARD APPROVED | F4: ACTUAL | G4: COMMITTED (open PR PO) | H4: ALLOTTED | J4: REMAINING1 (vs Allotted) | L4: REMAINING2 (vs Actual) | N4: Jan | O4: Feb | P4: Mar | Q4: Apr | R4: May | S4: Jun | T4: Jul | U4: Aug | V4: Sep | W4: Oct | X4: Nov | Y4: Dec | Z4: 2026 FORECAST | AA4: BALANCE
H5: PHP | I5: % | J5: PHP | K5: % | L5: PHP | M5: % | AA5: PHP | AB5: %
C6: A | D6: B | E6: C = A+B | F6: D | G6: E | H6: F = D+E | I6: G = F/C | J6: H = C-F | K6: I = H/C | L6: M = C-D | M6: N = M/C | Z6: J | AA6: K = C-J | AB6: L = K/C
B7: CORPORATE - HR | C7: 19700000 | E7: =C7+D7 -> 19700000 | F7: =SUMIFS(Monitoring!$AA:$AA,Monitoring!$D:$D,$B7,Monitoring!$F:$F,"N") -> 9832978.6 | G7: =SUMIFS(Monitoring!$AB:$AB,Monitoring!$D:$D,$B7,Monitoring!$F:$F,"N") -> 2203571.4 | H7: =SUM(F7:G7) -> 12036550 | I7: =H7/E7 -> 0.61099239 | J7: =E7-H7 -> 7663450 | K7: =J7/E7 -> 0.38900761 | L7: =E7-F7 -> 9867021.4 | M7: =L7/E7 -> 0.50086403 | N7: =SUMIFS(Monitoring!AG:AG,Monitoring!$D:$D,$B7,Monitoring!$F:$F,"N") -> 0 | O7: =SUMIFS(Monitoring!AH:AH,Monitoring!$D:$D,$B7,Monitoring!$F:$F,"N") -> 1828571.4 | P7: =SUMIFS(Monitoring!AI:AI,Monitoring!$D:$D,$B7,Monitoring!$F:$F,"N") -> 0 | Q7: =SUMIFS(Monitoring!AJ:AJ,Monitoring!$D:$D,$B7,Monitoring!$F:$F,"N") -> 0 | R7: =SUMIFS(Monitoring!AK:AK,Monitoring!$D:$D,$B7,Monitoring!$F:$F,"N") -> 1756428.6 | S7: =SUMIFS(Monitoring!AL:AL,Monitoring!$D:$D,$B7,Monitoring!$F:$F,"N") -> 2803335.7 | T7: =SUMIFS(Monitoring!AM:AM,Monitoring!$D:$D,$B7,Monitoring!$F:$F,"N") -> 775000 | U7: =SUMIFS(Monitoring!AN:AN,Monitoring!$D:$D,$B7,Monitoring!$F:$F,"N") -> 2669642.9 | V7: =SUMIFS(Monitoring!AO:AO,Monitoring!$D:$D,$B7,Monitoring!$F:$F,"N") -> 0 | W7: =SUMIFS(Monitoring!AP:AP,Monitoring!$D:$D,$B7,Monitoring!$F:$F,"N") -> 2203571.4 | X7: =SUMIFS(Monitoring!AQ:AQ,Monitoring!$D:$D,$B7,Monitoring!$F:$F,"N") -> 452232.58 | Y7: =SUMIFS(Monitoring!AR:AR,Monitoring!$D:$D,$B7,Monitoring!$F:$F,"N") -> 452232.58 | Z7: =SUM(N7:Y7) -> 12941015 | AA7: =E7-Z7 -> 6758984.8 | AB7: =AA7/E7 -> 0.34309568
B8: CORPORATE - IT | C8: 31000000 | E8: =C8+D8 -> 31000000 | F8: =SUMIFS(Monitoring!$AA:$AA,Monitoring!$D:$D,$B8,Monitoring!$F:$F,"N") -> 16165522 | G8: =SUMIFS(Monitoring!$AB:$AB,Monitoring!$D:$D,$B8,Monitoring!$F:$F,"N") -> 1562946.4 | H8: =SUM(F8:G8) -> 17728469 | I8: =H8/E8 -> 0.57188609 | J8: =E8-H8 -> 13271531 | K8: =J8/E8 -> 0.42811391 | L8: =E8-F8 -> 14834478 | M8: =L8/E8 -> 0.47853154 | N8: =SUMIFS(Monitoring!AG:AG,Monitoring!$D:$D,$B8,Monitoring!$F:$F,"N") -> 350000 | O8: =SUMIFS(Monitoring!AH:AH,Monitoring!$D:$D,$B8,Monitoring!$F:$F,"N") -> 0 | P8: =SUMIFS(Monitoring!AI:AI,Monitoring!$D:$D,$B8,Monitoring!$F:$F,"N") -> 0 | Q8: =SUMIFS(Monitoring!AJ:AJ,Monitoring!$D:$D,$B8,Monitoring!$F:$F,"N") -> 128571.43 | R8: =SUMIFS(Monitoring!AK:AK,Monitoring!$D:$D,$B8,Monitoring!$F:$F,"N") -> 13953571 | S8: =SUMIFS(Monitoring!AL:AL,Monitoring!$D:$D,$B8,Monitoring!$F:$F,"N") -> 0 | T8: =SUMIFS(Monitoring!AM:AM,Monitoring!$D:$D,$B8,Monitoring!$F:$F,"N") -> 0 | U8: =SUMIFS(Monitoring!AN:AN,Monitoring!$D:$D,$B8,Monitoring!$F:$F,"N") -> 424107.15 | V8: =SUMIFS(Monitoring!AO:AO,Monitoring!$D:$D,$B8,Monitoring!$F:$F,"N") -> 1309272.3 | W8: =SUMIFS(Monitoring!AP:AP,Monitoring!$D:$D,$B8,Monitoring!$F:$F,"N") -> 1562946.4 | X8: =SUMIFS(Monitoring!AQ:AQ,Monitoring!$D:$D,$B8,Monitoring!$F:$F,"N") -> 596617.46 | Y8: =SUMIFS(Monitoring!AR:AR,Monitoring!$D:$D,$B8,Monitoring!$F:$F,"N") -> 596617.46 | Z8: =SUM(N8:Y8) -> 18921704 | AA8: =E8-Z8 -> 12078296 | AB8: =AA8/E8 -> 0.38962246 | AC8: 1.6M upcoming laptops
B9: CORPORATE - ADMIN | C9: 2337486 | E9: =C9+D9 -> 2337486 | F9: =SUMIFS(Monitoring!$AA:$AA,Monitoring!$D:$D,$B9,Monitoring!$F:$F,"N") -> 138392.86 | G9: =SUMIFS(Monitoring!$AB:$AB,Monitoring!$D:$D,$B9,Monitoring!$F:$F,"N") -> 0 | H9: =SUM(F9:G9) -> 138392.86 | I9: =H9/E9 -> 0.059205856 | J9: =E9-H9 -> 2199093.1 | K9: =J9/E9 -> 0.94079414 | L9: =E9-F9 -> 2199093.1 | M9: =L9/E9 -> 0.94079414 | N9: =SUMIFS(Monitoring!AG:AG,Monitoring!$D:$D,$B9,Monitoring!$F:$F,"N") -> 0 | O9: =SUMIFS(Monitoring!AH:AH,Monitoring!$D:$D,$B9,Monitoring!$F:$F,"N") -> 138392.86 | P9: =SUMIFS(Monitoring!AI:AI,Monitoring!$D:$D,$B9,Monitoring!$F:$F,"N") -> 0 | Q9: =SUMIFS(Monitoring!AJ:AJ,Monitoring!$D:$D,$B9,Monitoring!$F:$F,"N") -> 0 | R9: =SUMIFS(Monitoring!AK:AK,Monitoring!$D:$D,$B9,Monitoring!$F:$F,"N") -> 0 | S9: =SUMIFS(Monitoring!AL:AL,Monitoring!$D:$D,$B9,Monitoring!$F:$F,"N") -> 0 | T9: =SUMIFS(Monitoring!AM:AM,Monitoring!$D:$D,$B9,Monitoring!$F:$F,"N") -> 0 | U9: =SUMIFS(Monitoring!AN:AN,Monitoring!$D:$D,$B9,Monitoring!$F:$F,"N") -> 0 | V9: =SUMIFS(Monitoring!AO:AO,Monitoring!$D:$D,$B9,Monitoring!$F:$F,"N") -> 0 | W9: =SUMIFS(Monitoring!AP:AP,Monitoring!$D:$D,$B9,Monitoring!$F:$F,"N") -> 0 | X9: =SUMIFS(Monitoring!AQ:AQ,Monitoring!$D:$D,$B9,Monitoring!$F:$F,"N") -> 0 | Y9: =SUMIFS(Monitoring!AR:AR,Monitoring!$D:$D,$B9,Monitoring!$F:$F,"N") -> 0 | Z9: =SUM(N9:Y9) -> 138392.86 | AA9: =E9-Z9 -> 2199093.1 | AB9: =AA9/E9 -> 0.94079414
B10: ESTATES | C10: 60000000 | E10: =C10+D10 -> 60000000 | F10: =SUMIFS(Monitoring!$AA:$AA,Monitoring!$D:$D,$B10,Monitoring!$F:$F,"N") -> 10913929 | G10: =SUMIFS(Monitoring!$AB:$AB,Monitoring!$D:$D,$B10,Monitoring!$F:$F,"N") -> 35518593 | H10: =SUM(F10:G10) -> 46432522 | I10: =H10/E10 -> 0.77387536 | J10: =E10-H10 -> 13567478 | K10: =J10/E10 -> 0.22612464 | L10: =E10-F10 -> 49086071 | M10: =L10/E10 -> 0.81810119 | N10: =SUMIFS(Monitoring!AG:AG,Monitoring!$D:$D,$B10,Monitoring!$F:$F,"N") -> 0 | O10: =SUMIFS(Monitoring!AH:AH,Monitoring!$D:$D,$B10,Monitoring!$F:$F,"N") -> 0 | P10: =SUMIFS(Monitoring!AI:AI,Monitoring!$D:$D,$B10,Monitoring!$F:$F,"N") -> 0 | Q10: =SUMIFS(Monitoring!AJ:AJ,Monitoring!$D:$D,$B10,Monitoring!$F:$F,"N") -> 982142.86 | R10: =SUMIFS(Monitoring!AK:AK,Monitoring!$D:$D,$B10,Monitoring!$F:$F,"N") -> 7096071.4 | S10: =SUMIFS(Monitoring!AL:AL,Monitoring!$D:$D,$B10,Monitoring!$F:$F,"N") -> 1517857.1 | T10: =SUMIFS(Monitoring!AM:AM,Monitoring!$D:$D,$B10,Monitoring!$F:$F,"N") -> -83928.57 | U10: =SUMIFS(Monitoring!AN:AN,Monitoring!$D:$D,$B10,Monitoring!$F:$F,"N") -> 0 | V10: =SUMIFS(Monitoring!AO:AO,Monitoring!$D:$D,$B10,Monitoring!$F:$F,"N") -> 1401785.7 | W10: =SUMIFS(Monitoring!AP:AP,Monitoring!$D:$D,$B10,Monitoring!$F:$F,"N") -> 35518593 | X10: =SUMIFS(Monitoring!AQ:AQ,Monitoring!$D:$D,$B10,Monitoring!$F:$F,"N") -> 3262664.8 | Y10: =SUMIFS(Monitoring!AR:AR,Monitoring!$D:$D,$B10,Monitoring!$F:$F,"N") -> 3262664.8 | Z10: =SUM(N10:Y10) -> 52957851 | AA10: =E10-Z10 -> 7042148.7 | AB10: =AA10/E10 -> 0.11736915
B11: MALLS | C11: =Malls!$G$1 -> 1.1320605e+08 | E11: =C11+D11 -> 1.1320605e+08 | F11: =SUMIFS(Monitoring!$AA:$AA,Monitoring!$D:$D,$B11,Monitoring!$F:$F,"N") -> 27138755 | G11: =SUMIFS(Monitoring!$AB:$AB,Monitoring!$D:$D,$B11,Monitoring!$F:$F,"N") -> 55946400 | H11: =SUM(F11:G11) -> 83085155 | I11: =H11/E11 -> 0.73392856 | J11: =E11-H11 -> 30120898 | K11: =J11/E11 -> 0.26607144 | L11: =E11-F11 -> 86067298 | M11: =L11/E11 -> 0.76027117 | N11: =SUMIFS(Monitoring!AG:AG,Monitoring!$D:$D,$B11,Monitoring!$F:$F,"N") -> 303160.72 | O11: =SUMIFS(Monitoring!AH:AH,Monitoring!$D:$D,$B11,Monitoring!$F:$F,"N") -> 192133.92 | P11: =SUMIFS(Monitoring!AI:AI,Monitoring!$D:$D,$B11,Monitoring!$F:$F,"N") -> 4099106 | Q11: =SUMIFS(Monitoring!AJ:AJ,Monitoring!$D:$D,$B11,Monitoring!$F:$F,"N") -> 5106499.9 | R11: =SUMIFS(Monitoring!AK:AK,Monitoring!$D:$D,$B11,Monitoring!$F:$F,"N") -> 1056861 | S11: =SUMIFS(Monitoring!AL:AL,Monitoring!$D:$D,$B11,Monitoring!$F:$F,"N") -> 1758947.2 | T11: =SUMIFS(Monitoring!AM:AM,Monitoring!$D:$D,$B11,Monitoring!$F:$F,"N") -> 4291527.3 | U11: =SUMIFS(Monitoring!AN:AN,Monitoring!$D:$D,$B11,Monitoring!$F:$F,"N") -> 8630965.4 | V11: =SUMIFS(Monitoring!AO:AO,Monitoring!$D:$D,$B11,Monitoring!$F:$F,"N") -> 1699553.6 | W11: =SUMIFS(Monitoring!AP:AP,Monitoring!$D:$D,$B11,Monitoring!$F:$F,"N") -> 55946400 | X11: =SUMIFS(Monitoring!AQ:AQ,Monitoring!$D:$D,$B11,Monitoring!$F:$F,"N") -> 26185449 | Y11: =SUMIFS(Monitoring!AR:AR,Monitoring!$D:$D,$B11,Monitoring!$F:$F,"N") -> 26185449 | Z11: =SUM(N11:Y11) -> 1.3545605e+08 | AA11: =E11-Z11 -> -22250000 | AB11: =AA11/E11 -> -0.19654426
B12: OFFICES | C12: 67300000 | E12: =C12+D12 -> 67300000 | F12: =SUMIFS(Monitoring!$AA:$AA,Monitoring!$D:$D,$B12,Monitoring!$F:$F,"N") -> 33367018 | G12: =SUMIFS(Monitoring!$AB:$AB,Monitoring!$D:$D,$B12,Monitoring!$F:$F,"N") -> 20169252 | H12: =SUM(F12:G12) -> 53536270 | I12: =H12/E12 -> 0.79548692 | J12: =E12-H12 -> 13763730 | K12: =J12/E12 -> 0.20451308 | L12: =E12-F12 -> 33932982 | M12: =L12/E12 -> 0.50420479 | N12: =SUMIFS(Monitoring!AG:AG,Monitoring!$D:$D,$B12,Monitoring!$F:$F,"N") -> 0 | O12: =SUMIFS(Monitoring!AH:AH,Monitoring!$D:$D,$B12,Monitoring!$F:$F,"N") -> 3563196.5 | P12: =SUMIFS(Monitoring!AI:AI,Monitoring!$D:$D,$B12,Monitoring!$F:$F,"N") -> 6383928.6 | Q12: =SUMIFS(Monitoring!AJ:AJ,Monitoring!$D:$D,$B12,Monitoring!$F:$F,"N") -> 9682285.7 | R12: =SUMIFS(Monitoring!AK:AK,Monitoring!$D:$D,$B12,Monitoring!$F:$F,"N") -> 410714.29 | S12: =SUMIFS(Monitoring!AL:AL,Monitoring!$D:$D,$B12,Monitoring!$F:$F,"N") -> 7600107.2 | T12: =SUMIFS(Monitoring!AM:AM,Monitoring!$D:$D,$B12,Monitoring!$F:$F,"N") -> 403571.43 | U12: =SUMIFS(Monitoring!AN:AN,Monitoring!$D:$D,$B12,Monitoring!$F:$F,"N") -> 1707142.9 | V12: =SUMIFS(Monitoring!AO:AO,Monitoring!$D:$D,$B12,Monitoring!$F:$F,"N") -> 3616071.4 | W12: =SUMIFS(Monitoring!AP:AP,Monitoring!$D:$D,$B12,Monitoring!$F:$F,"N") -> 20169252 | X12: =SUMIFS(Monitoring!AQ:AQ,Monitoring!$D:$D,$B12,Monitoring!$F:$F,"N") -> 6881865.1 | Y12: =SUMIFS(Monitoring!AR:AR,Monitoring!$D:$D,$B12,Monitoring!$F:$F,"N") -> 6881865.1 | Z12: =SUM(N12:Y12) -> 67300000 | AA12: =E12-Z12 -> 0.004285723 | AB12: =AA12/E12 -> 6.3680876e-11
B13: RESIDENTIAL | C13: 50000000 | E13: =C13+D13 -> 50000000 | F13: =SUMIFS(Monitoring!$AA:$AA,Monitoring!$D:$D,$B13,Monitoring!$F:$F,"N") -> 8244582.9 | G13: =SUMIFS(Monitoring!$AB:$AB,Monitoring!$D:$D,$B13,Monitoring!$F:$F,"N") -> 3777253.7 | H13: =SUM(F13:G13) -> 12021837 | I13: =H13/E13 -> 0.24043673 | J13: =E13-H13 -> 37978163 | K13: =J13/E13 -> 0.75956327 | L13: =E13-F13 -> 41755417 | M13: =L13/E13 -> 0.83510834 | N13: =SUMIFS(Monitoring!AG:AG,Monitoring!$D:$D,$B13,Monitoring!$F:$F,"N") -> 276196.43 | O13: =SUMIFS(Monitoring!AH:AH,Monitoring!$D:$D,$B13,Monitoring!$F:$F,"N") -> 6428571.4 | P13: =SUMIFS(Monitoring!AI:AI,Monitoring!$D:$D,$B13,Monitoring!$F:$F,"N") -> 12767.85 | Q13: =SUMIFS(Monitoring!AJ:AJ,Monitoring!$D:$D,$B13,Monitoring!$F:$F,"N") -> -9.3132257e-10 | R13: =SUMIFS(Monitoring!AK:AK,Monitoring!$D:$D,$B13,Monitoring!$F:$F,"N") -> 70526.79 | S13: =SUMIFS(Monitoring!AL:AL,Monitoring!$D:$D,$B13,Monitoring!$F:$F,"N") -> 1192187.5 | T13: =SUMIFS(Monitoring!AM:AM,Monitoring!$D:$D,$B13,Monitoring!$F:$F,"N") -> 62500 | U13: =SUMIFS(Monitoring!AN:AN,Monitoring!$D:$D,$B13,Monitoring!$F:$F,"N") -> 201832.86 | V13: =SUMIFS(Monitoring!AO:AO,Monitoring!$D:$D,$B13,Monitoring!$F:$F,"N") -> 0 | W13: =SUMIFS(Monitoring!AP:AP,Monitoring!$D:$D,$B13,Monitoring!$F:$F,"N") -> 3777253.7 | X13: =SUMIFS(Monitoring!AQ:AQ,Monitoring!$D:$D,$B13,Monitoring!$F:$F,"N") -> 1036030.5 | Y13: =SUMIFS(Monitoring!AR:AR,Monitoring!$D:$D,$B13,Monitoring!$F:$F,"N") -> 1036030.5 | Z13: =SUM(N13:Y13) -> 14093898 | AA13: =E13-Z13 -> 35906102 | AB13: =AA13/E13 -> 0.71812205
B14: TOTAL | C14: =SUM(C7:C13) -> 3.4354354e+08 | D14: =SUM(D7:D13) -> 0 | E14: =SUM(E7:E13) -> 3.4354354e+08 | F14: =SUM(F7:F13) -> 1.0580118e+08 | G14: =SUM(G7:G13) -> 1.1917802e+08 | H14: =SUM(H7:H13) -> 2.2497919e+08 | I14: =H14/E14 -> 0.65487826 | J14: =SUM(J7:J13) -> 1.1856434e+08 | K14: =J14/E14 -> 0.34512174 | L14: =SUM(L7:L13) -> 2.3774236e+08 | M14: =L14/E14 -> 0.69202978 | N14: =SUM(N7:N13) -> 929357.15 | O14: =SUM(O7:O13) -> 12150866 | P14: =SUM(P7:P13) -> 10495802 | Q14: =SUM(Q7:Q13) -> 15899500 | R14: =SUM(R7:R13) -> 24344173 | S14: =SUM(S7:S13) -> 14872435 | T14: =SUM(T7:T13) -> 5448670.1 | U14: =SUM(U7:U13) -> 13633691 | ... AA14: =SUM(AA7:AA13) -> 41734625 | AB14: =AA14/E14 -> 0.12148278
F15: =F14-SUMIF(Monitoring!$F:$F,"N",Monitoring!AA:AA) -> 0 | G15: =G14-SUMIF(Monitoring!$F:$F,"N",Monitoring!AB:AB) -> 0 | H15: =H14-SUMIF(Monitoring!$F:$F,"N",Monitoring!AC:AC) -> 0 | N15: =N14-SUMIF(Monitoring!$F:$F,"N",Monitoring!AG:AG) -> 0 | O15: =O14-SUMIF(Monitoring!$F:$F,"N",Monitoring!AH:AH) -> 0 | P15: =P14-SUMIF(Monitoring!$F:$F,"N",Monitoring!AI:AI) -> 0 | Q15: =Q14-SUMIF(Monitoring!$F:$F,"N",Monitoring!AJ:AJ) -> 0 | R15: =R14-SUMIF(Monitoring!$F:$F,"N",Monitoring!AK:AK) -> 0 | S15: =S14-SUMIF(Monitoring!$F:$F,"N",Monitoring!AL:AL) -> 0 | T15: =T14-SUMIF(Monitoring!$F:$F,"N",Monitoring!AM:AM) -> 0 | U15: =U14-SUMIF(Monitoring!$F:$F,"N",Monitoring!AN:AN) -> 0 | V15: =V14-SUMIF(Monitoring!$F:$F,"N",Monitoring!AO:AO) -> 0 | W15: =W14-SUMIF(Monitoring!$F:$F,"N",Monitoring!AP:AP) -> 0 | X15: =X14-SUMIF(Monitoring!$F:$F,"N",Monitoring!AQ:AQ) -> 0 | Y15: =Y14-SUMIF(Monitoring!$F:$F,"N",Monitoring!AR:AR) -> 0 | Z15: =Z14-SUMIF(Monitoring!$F:$F,"N",Monitoring!AS:AS) -> 0
B16: Board Approved vs SAP IO
B17: (without Special Projects)
B18: SBU | C18: ORIGINAL BOARD APPROVED | D18: ADDITIONAL/ REDUCTION | E18: TOTAL BOARD APPROVED | F18: SAP IO | H18: REMAINING
F19: PHP | G19: % | H19: PHP | I19: %
C20: A | D20: B | E20: C = A+B | F20: D | G20: E = D/C | H20: F = C-D | I20: G = F/C
B21: CORPORATE - HR | C21: 19700000 | E21: =C21+D21 -> 19700000 | F21: =SUMIFS(Monitoring!R:R,Monitoring!D:D,Summary!B21,Monitoring!F:F,"N") -> 13721451 | G21: =F21/E21 -> 0.69652035 | H21: =E21-F21 -> 5978549.1 | I21: =H21/E21 -> 0.30347965
B22: CORPORATE - IT | C22: 31000000 | E22: =C22+D22 -> 31000000 | F22: =SUMIFS(Monitoring!R:R,Monitoring!D:D,Summary!B22,Monitoring!F:F,"N") -> 18921704 | G22: =F22/E22 -> 0.61037754 | H22: =E22-F22 -> 12078296 | I22: =H22/E22 -> 0.38962246
B23: CORPORATE - ADMIN | C23: 2337486 | E23: =C23+D23 -> 2337486 | F23: =SUMIFS(Monitoring!R:R,Monitoring!D:D,Summary!B23,Monitoring!F:F,"N") -> 138392.86 | G23: =F23/E23 -> 0.059205856 | H23: =E23-F23 -> 2199093.1 | I23: =H23/E23 -> 0.94079414
B24: ESTATES | C24: 60000000 | E24: =C24+D24 -> 60000000 | F24: =SUMIFS(Monitoring!R:R,Monitoring!D:D,Summary!B24,Monitoring!F:F,"N") -> 52957851 | G24: =F24/E24 -> 0.88263085 | H24: =E24-F24 -> 7042148.7 | I24: =H24/E24 -> 0.11736915
B25: MALLS | C25: =Malls!$G$1 -> 1.1320605e+08 | E25: =C25+D25 -> 1.1320605e+08 | F25: =SUMIFS(Monitoring!R:R,Monitoring!D:D,Summary!B25,Monitoring!F:F,"N") -> 1.3795605e+08 | G25: =F25/E25 -> 1.2186279 | H25: =E25-F25 -> -24750000 | I25: =H25/E25 -> -0.21862789
B26: OFFICES | C26: 67300000 | E26: =C26+D26 -> 67300000 | F26: =SUMIFS(Monitoring!R:R,Monitoring!D:D,Summary!B26,Monitoring!F:F,"N") -> 66298214 | G26: =F26/E26 -> 0.98511463 | H26: =E26-F26 -> 1001785.7 | I26: =H26/E26 -> 0.014885375
B27: RESIDENTIAL | C27: 50000000 | E27: =C27+D27 -> 50000000 | F27: =SUMIFS(Monitoring!R:R,Monitoring!D:D,Summary!B27,Monitoring!F:F,"N") -> 14093898 | G27: =F27/E27 -> 0.28187795 | H27: =E27-F27 -> 35906102 | I27: =H27/E27 -> 0.71812205
B28: TOTAL | C28: =SUM(C21:C27) -> 3.4354354e+08 | D28: =SUM(D21:D27) -> 0 | E28: =SUM(E21:E27) -> 3.4354354e+08 | F28: =SUM(F21:F27) -> 3.0408756e+08 | G28: =F28/E28 -> 0.88515 | H28: =SUM(H21:H27) -> 39455976 | I28: =H28/E28 -> 0.11485
B30: Board Approved vs Allotted
B31: (with Special Projects)
B32: SBU | C32: ORIGINAL BOARD APPROVED | D32: ADDITIONAL/ REDUCTION | E32: TOTAL BOARD APPROVED | F32: ACTUAL | G32: COMMITTED (open PR PO) | H32: ALLOTTED | J32: AVAILABLE1 | L32: AVAILABLE2 | N32: Jan | O32: Feb | P32: Mar | Q32: Apr | R32: May | S32: Jun | T32: Jul | U32: Aug | V32: Sep | W32: Oct | X32: Nov | Y32: Dec | Z32: 2026 FORECAST | AA32: BALANCE
H33: PHP | I33: % | J33: PHP | K33: % | L33: PHP | M33: % | AA33: PHP | AB33: %
C34: A | D34: B | E34: C = A+B | F34: D | G34: E | H34: F = D+E | I34: G = F/C | J34: H = C-F | K34: I = H/C | Z34: J | AA34: K = C-J | AB34: L = K/C
B35: CORPORATE - HR | C35: 19700000 | E35: =C35+D35 -> 19700000 | F35: =SUMIF(Monitoring!$D:$D,Summary!$B35,Monitoring!$AA:$AA) -> 9832978.6 | G35: =SUMIF(Monitoring!$D:$D,Summary!$B35,Monitoring!$AB:$AB) -> 2203571.4 | H35: =SUM(F35:G35) -> 12036550 | I35: =H35/E35 -> 0.61099239 | J35: =E35-H35 -> 7663450 | K35: =J35/E35 -> 0.38900761 | Z35: =SUM(N35:Y35) -> 0 | AA35: =E35-Z35 -> 19700000 | AB35: =AA35/E35 -> 1
B36: CORPORATE - IT | C36: 31000000 | E36: =C36+D36 -> 31000000 | F36: =SUMIF(Monitoring!$D:$D,Summary!$B36,Monitoring!$AA:$AA) -> 16165522 | G36: =SUMIF(Monitoring!$D:$D,Summary!$B36,Monitoring!$AB:$AB) -> 1562946.4 | H36: =SUM(F36:G36) -> 17728469 | I36: =H36/E36 -> 0.57188609 | J36: =E36-H36 -> 13271531 | K36: =J36/E36 -> 0.42811391 | Z36: =SUM(N36:Y36) -> 0 | AA36: =E36-Z36 -> 31000000 | AB36: =AA36/E36 -> 1
B37: CORPORATE - ADMIN | C37: 2337486 | E37: =C37+D37 -> 2337486 | F37: =SUMIF(Monitoring!$D:$D,Summary!$B37,Monitoring!$AA:$AA) -> 138392.86 | G37: =SUMIF(Monitoring!$D:$D,Summary!$B37,Monitoring!$AB:$AB) -> 0 | H37: =SUM(F37:G37) -> 138392.86 | I37: =H37/E37 -> 0.059205856 | J37: =E37-H37 -> 2199093.1 | K37: =J37/E37 -> 0.94079414 | Z37: =SUM(N37:Y37) -> 0 | AA37: =E37-Z37 -> 2337486 | AB37: =AA37/E37 -> 1
B38: ESTATES | C38: 60000000 | E38: =C38+D38 -> 60000000 | F38: =SUMIF(Monitoring!$D:$D,Summary!$B38,Monitoring!$AA:$AA) -> 50481169 | G38: =SUMIF(Monitoring!$D:$D,Summary!$B38,Monitoring!$AB:$AB) -> 1.4525823e+08 | H38: =SUM(F38:G38) -> 1.9573939e+08 | I38: =H38/E38 -> 3.2623232 | J38: =E38-H38 -> -1.3573939e+08 | K38: =J38/E38 -> -2.2623232 | Z38: =SUM(N38:Y38) -> 0 | AA38: =E38-Z38 -> 60000000 | AB38: =AA38/E38 -> 1
B39: MALLS | C39: =Malls!$G$1 -> 1.1320605e+08 | E39: =C39+D39 -> 1.1320605e+08 | F39: =SUMIF(Monitoring!$D:$D,Summary!$B39,Monitoring!$AA:$AA) -> 27138755 | G39: =SUMIF(Monitoring!$D:$D,Summary!$B39,Monitoring!$AB:$AB) -> 55946400 | H39: =SUM(F39:G39) -> 83085155 | I39: =H39/E39 -> 0.73392856 | J39: =E39-H39 -> 30120898 | K39: =J39/E39 -> 0.26607144 | Z39: =SUM(N39:Y39) -> 0 | AA39: =E39-Z39 -> 1.1320605e+08 | AB39: =AA39/E39 -> 1
B40: OFFICES | C40: 67300000 | E40: =C40+D40 -> 67300000 | F40: =SUMIF(Monitoring!$D:$D,Summary!$B40,Monitoring!$AA:$AA) -> 42886794 | G40: =SUMIF(Monitoring!$D:$D,Summary!$B40,Monitoring!$AB:$AB) -> 25379823 | H40: =SUM(F40:G40) -> 68266617 | I40: =H40/E40 -> 1.0143628 | J40: =E40-H40 -> -966617.47 | K40: =J40/E40 -> -0.014362815 | Z40: =SUM(N40:Y40) -> 0 | AA40: =E40-Z40 -> 67300000 | AB40: =AA40/E40 -> 1
B41: RESIDENTIAL | C41: 50000000 | E41: =C41+D41 -> 50000000 | F41: =SUMIF(Monitoring!$D:$D,Summary!$B41,Monitoring!$AA:$AA) -> 8244582.9 | G41: =SUMIF(Monitoring!$D:$D,Summary!$B41,Monitoring!$AB:$AB) -> 3777253.7 | H41: =SUM(F41:G41) -> 12021837 | I41: =H41/E41 -> 0.24043673 | J41: =E41-H41 -> 37978163 | K41: =J41/E41 -> 0.75956327 | Z41: =SUM(N41:Y41) -> 0 | AA41: =E41-Z41 -> 50000000 | AB41: =AA41/E41 -> 1
B42: TOTAL | C42: =SUM(C35:C41) -> 3.4354354e+08 | D42: =SUM(D35:D41) -> 0 | E42: =SUM(E35:E41) -> 3.4354354e+08 | F42: =SUM(F35:F41) -> 1.5488819e+08 | G42: =SUM(G35:G41) -> 234128221 | H42: =SUM(H35:H41) -> 3.8901642e+08 | I42: =H42/E42 -> 1.1323642 | J42: =SUM(J35:J41) -> -45472876 | K42: =J42/E42 -> -0.13236423 | N42: =SUM(N35:N41) -> 0 | Y42: =SUM(Y35:Y41) -> 0 | Z42: =SUM(Z35:Z41) -> 0 | AA42: =SUM(AA35:AA41) -> 3.4354354e+08 | AB42: =AA42/E42 -> 1
...

Sheet SAP Report
A1: Updated as of | B1: 09/15/2026
C2: =SUBTOTAL(9,C4:C179) -> 7.0766826e+08 | D2: =SUBTOTAL(9,D4:D179) -> 1.5488819e+08 | E2: =SUBTOTAL(9,E4:E179) -> 234128221 | F2: =SUBTOTAL(9,F4:F179) -> 3.8901642e+08 | G2: =SUBTOTAL(9,G4:G179) -> 3.1865184e+08
A3: IO Number | B3: Description | C3: Budget | D3: Actual | E3: Commitment | F3: Allotted | G3: Available
A4: 10000820 | B4: GH IMPROVEMENT OF VMALL PARK | C4: 278125 | E4: 278125 | F4: 278125 | G4: =C4-F4 -> 0
A5: 10001021 | B5: GH PH1 STREETSCAPE PROJECT | C5: 4855625 | E5: 4855625 | F5: 4855625 | G5: =C5-F5 -> 0
A6: 10001072 | B6: GH RFDCK/CNOPIES/PRMTR WALL | C6: 142000 | E6: 142000 | F6: 142000 | G6: =C6-F6 -> 0
A7: 10001075 | B7: CC STP UPGRADE | G7: =C7-F7 -> 0
A8: 10001134 | B8: GH TIANGGE EIFS DROPWALL | C8: 789517.86 | E8: 789517.86 | F8: 789517.86 | G8: =C8-F8 -> 0
A9: 10001136 | B9: CCIC SALES OFFICE SPLIT-TYPE | C9: 982142.86 | D9: 982142.86 | F9: 982142.86 | G9: =C9-F9 -> 0
A10: 10001140 | B10: CCIC MEZZANINE 2 AIRCON UNIT | C10: 232142.86 | E10: 232142.86 | F10: 232142.86 | G10: =C10-F10 -> 0
A11: 10001143 | B11: CCIC EXTERIOR WALL & CEILING | C11: 308303.57 | G11: =C11-F11 -> 308303.57
A12: 10001190 | B12: SC4 VRF SYSTEM RECONDITIONIN | C12: 2400000 | D12: 2400000 | F12: 2400000 | G12: =C12-F12 -> 0
A13: 10001220 | B13: GH ESTATES LIFT STATION | C13: 99196.43 | E13: 99196.43 | F13: 99196.43 | G13: =C13-F13 -> 0
A14: 10001254 | B14: ES CONSTRUCTION OF OMD ADMIN | C14: 32193.08 | E14: 32193.08 | F14: 32193.08 | G14: =C14-F14 -> 0
A15: 10001262 | B15: GH NEW MALL REWATERPROOFING | C15: 767321.43 | D15: 417857.14 | E15: 349464.28 | F15: 767321.42 | G15: =C15-F15 -> 0.01
A16: 10001269 | B16: EONS ELEVATORS PARTS REPLACE | C16: 560714.29 | D16: 560714.29 | F16: 560714.29 | G16: =C16-F16 -> 0
A17: 10001270 | B17: ESW LIFT STATION REHABILITAT | C17: 437500 | D17: 437500 | F17: 437500 | G17: =C17-F17 -> 0
A18: 10001281 | B18: SC4 WATER PROOFING OF ROOF D | C18: 3004771.5 | D18: 1973033.9 | E18: 1031737.5 | F18: 3004771.5 | G18: =C18-F18 -> 0
A19: 10001288 | B19: ES EAST WING 2024 SPACE RE-C | C19: 7500 | E19: 7500 | F19: 7500 | G19: =C19-F19 -> 0
A20: 10001289 | B20: ES MAIN 2025 SPACE RE-CUT & | C20: 42857.14 | E20: 42857.14 | F20: 42857.14 | G20: =C20-F20 -> 0
A21: 10001294 | B21: GH TIANGGE STALLS ELECTRICAL | C21: 4560714.3 | D21: 4253567.6 | F21: 4253567.6 | G21: =C21-F21 -> 307146.69
A22: 10001296 | B22: GH MALL ADMIN RELOCATION AND | C22: 506471.03 | D22: 437499.99 | E22: 20810.32 | F22: 458310.31 | G22: =C22-F22 -> 48160.72
A23: 10001298 | B23: CC DRAINAGE IMPROVEMENT PH1A | C23: 7190.4 | D23: -0.01 | E23: 7190.4 | F23: 7190.39 | G23: =C23-F23 -> 0.01
A24: 10001302 | B24: GH TENANT RECUTS | C24: 278743.18 | E24: 278743.18 | F24: 278743.18 | G24: =C24-F24 -> 0
A25: 10001305 | B25: GH ANNEX ALFRESCO AREA COLUM | C25: 356250 | E25: 356250 | F25: 356250 | G25: =C25-F25 -> 0
A26: 10001308 | B26: CC PASIG CIVIC CENTER | C26: 25714286 | G26: =C26-F26 -> 25714286
A27: 10001311 | B27: SC2&3 WATER PROOFING OF ROOF | C27: 3660714.3 | D27: 3161591.1 | E27: 499123.19 | F27: 3660714.3 | G27: =C27-F27 -> 0
A28: 10001312 | B28: EM EAST WING CHAPEL AIRCON A | C28: 12232.14 | E28: 12232.14 | F28: 12232.14 | G28: =C28-F28 -> 0
A29: 10001314 | B29: GH TOWER BIR FIT-OUT | C29: 10217698 | D29: 8096919.1 | E29: 1429857.1 | F29: 9526776.2 | G29: =C29-F29 -> 690921.41
A30: 10001315 | B30: GH MALL VIP READER SYSTEM FO | C30: 26321.43 | D30: 133464.29 | F30: 133464.29 | G30: =C30-F30 -> -107142.86
A31: 10001320 | B31: THE STRIP SEISMIC ACCELEROGR | C31: 875000 | E31: 875000 | F31: 875000 | G31: =C31-F31 -> 0
A32: 10001322 | B32: CC DRAINAGE IMPROVEMENT PHAS | C32: 15000000 | D32: 6300000 | E32: 8700000 | F32: 15000000 | G32: =C32-F32 -> 0
A33: 10001340 | B33: IBP ACP REPLACEMENT & PUMP R | C33: 285714.29 | D33: 285714.29 | F33: 285714.29 | G33: =C33-F33 -> 0
A34: 10001341 | B34: CC PARK REDEVELOPMENT | C34: 50718878 | D34: 24715944 | E34: 20320127 | F34: 45036072 | G34: =C34-F34 -> 5682806.2
A35: 10001342 | B35: GH EXISTING MALL PRE-WATERPR | C35: 341960.05 | D35: 208214.29 | E35: 133745.76 | F35: 341960.05 | G35: =C35-F35 -> 0
A36: 10001348 | B36: GH VMALL CHAPEL RENOVATION | C36: 486257.14 | E36: 486257.14 | F36: 486257.14 | G36: =C36-F36 -> 0
A37: 10001350 | B37: CAPITOL COMMONS IMPROVEMENTS | C37: 20168929 | D37: 11986161 | E37: 3966040.4 | F37: 15952201 | G37: =C37-F37 -> 4216727.5
A38: 10001360 | B38: ESWW WATERPROOFING | C38: 2437500 | D38: 2437500 | F38: 2437500 | G38: =C38-F38 -> 0
A39: 10001361 | B39: SC2&3 REHAB OF VRF | C39: 2901785.7 | D39: 2901785.7 | F39: 2901785.7 | G39: =C39-F39 -> 0
A40: 10001362 | B40: CC STP REHAB AND REPAIR | C40: 366071.43 | D40: 366071.43 | F40: 366071.43 | G40: =C40-F40 -> 0
...

Sheet Actual
F1: =SUBTOTAL(9,F3:F1048576) -> 1.5488819e+08
A2: Order | B2: CO object name | C2: Cost element name | D2: Purchasing Document | E2: Ref Document Number | F2: Val.in rep.cur. | G2: Purchase order text | H2: Document Header Text | I2: Total quantity | J2: Offsetting account type | K2: Offsetting acct no. | L2: Name of offsetting account | M2: Period | N2: Month
A3: 10001136 | B3: CCIC SALES OFFICE SPLIT-TYPE AIRCON | C3: IO CAPEX | D3: 4500023106 | E3: 5000056499 | F3: 982142.86 | G3: Supply and installation of 4Units AC | I3: 1 | J3: S | K3: 21301102 | L3: Trade A/P Clearing | M3: 6 | N3: =_xlfn.XLOOKUP(M3,$Q$3:$Q$14,$R$3:$R$14) -> Jun | Q3: 1 | R3: Jan
A4: 10001190 | B4: SC4 VRF SYSTEM RECONDITIONING | C4: IO CAPEX | D4: 4500030671 | E4: 5000055823 | F4: 2400000 | G4: Rehabilitation of VRF at SC4 | I4: 1 | J4: S | K4: 21301102 | L4: Trade A/P Clearing | M4: 4 | N4: =_xlfn.XLOOKUP(M4,$Q$3:$Q$14,$R$3:$R$14) -> Apr | Q4: 2 | R4: Feb
A5: 10001262 | B5: GH NEW MALL REWATERPROOFING PROJECT | C5: IO CAPEX | D5: 4500028476 | E5: 5000055813 | F5: 417857.14 | G5: Waterproofing and Facade Works at GH Ph1 | I5: 0.312 | J5: S | K5: 21301102 | L5: Trade A/P Clearing | M5: 4 | N5: =_xlfn.XLOOKUP(M5,$Q$3:$Q$14,$R$3:$R$14) -> Apr | Q5: 3 | R5: Mar
A6: 10001269 | B6: EONS ELEVATORS PARTS REPLACEMENT | C6: IO CAPEX | D6: 4500030559 | E6: 5000055592 | F6: 44642.86 | G6: PARTS REPLACEMENT OF FREIGHT ELEVATOR 1 | I6: 1 | J6: S | K6: 21301102 | L6: Trade A/P Clearing | M6: 4 | N6: =_xlfn.XLOOKUP(M6,$Q$3:$Q$14,$R$3:$R$14) -> Apr | Q6: 4 | R6: Apr
A7: 10001269 | B7: EONS ELEVATORS PARTS REPLACEMENT | C7: IO CAPEX | D7: 4500030559 | E7: 5000055592 | F7: 145535.71 | G7: PARTS REPLACEMENT PASSENGER ELEVATOR 3 | I7: 1 | J7: S | K7: 21301102 | L7: Trade A/P Clearing | M7: 4 | N7: =_xlfn.XLOOKUP(M7,$Q$3:$Q$14,$R$3:$R$14) -> Apr | Q7: 5 | R7: May
A8: 10001269 | B8: EONS ELEVATORS PARTS REPLACEMENT | C8: IO CAPEX | D8: 4500030559 | E8: 5000055592 | F8: 178571.43 | G8: PARTS REPLACEMENT PASSENGER ELEVATOR 2 | I8: 1 | J8: S | K8: 21301102 | L8: Trade A/P Clearing | M8: 4 | N8: =_xlfn.XLOOKUP(M8,$Q$3:$Q$14,$R$3:$R$14) -> Apr | Q8: 6 | R8: Jun
A9: 10001269 | B9: EONS ELEVATORS PARTS REPLACEMENT | C9: IO CAPEX | D9: 4500030559 | E9: 5000055592 | F9: 191964.29 | G9: PARTS REPLACEMENT PASSENGER ELEVATOR 1 | I9: 1 | J9: S | K9: 21301102 | L9: Trade A/P Clearing | M9: 4 | N9: =_xlfn.XLOOKUP(M9,$Q$3:$Q$14,$R$3:$R$14) -> Apr | Q9: 7 | R9: Jul
A10: 10001270 | B10: ESW LIFT STATION REHABILITATION | C10: IO CAPEX | D10: 4500030613 | E10: 5000055824 | F10: 80357.14 | G10: S&I OF DUPLEX PUMP CONTROLLER | I10: 1 | J10: S | K10: 21301102 | L10: Trade A/P Clearing | M10: 4 | N10: =_xlfn.XLOOKUP(M10,$Q$3:$Q$14,$R$3:$R$14) -> Apr | Q10: 8 | R10: Aug
A11: 10001270 | B11: ESW LIFT STATION REHABILITATION | C11: IO CAPEX | D11: 4500030613 | E11: 5000055824 | F11: 357142.86 | G11: S&I OF 2 UNITS BLADDER MEMBRANE | I11: 1 | J11: S | K11: 21301102 | L11: Trade A/P Clearing | M11: 4 | N11: =_xlfn.XLOOKUP(M11,$Q$3:$Q$14,$R$3:$R$14) -> Apr | Q11: 9 | R11: Sep
A12: 10001281 | B12: SC4 WATER PROOFING OF ROOF DECK FLOORING | C12: IO CAPEX | D12: 4500028439 | E12: 5000054530 | F12: 1473910.7 | G12: WATERPROOFING OF SC4 - 3,250 sq.m | I12: 0.4 | J12: S | K12: 21301102 | L12: Trade A/P Clearing | M12: 2 | N12: =_xlfn.XLOOKUP(M12,$Q$3:$Q$14,$R$3:$R$14) -> Feb | Q12: 10 | R12: Oct
A13: 10001281 | B13: SC4 WATER PROOFING OF ROOF DECK FLOORING | C13: IO CAPEX | D13: 4500030775 | E13: 5000055037 | F13: 499123.19 | G13: WATERPROOFING OF SC 2 (352.42sqm) | I13: 1 | J13: S | K13: 21301102 | L13: Trade A/P Clearing | M13: 3 | N13: =_xlfn.XLOOKUP(M13,$Q$3:$Q$14,$R$3:$R$14) -> Mar | Q13: 11 | R13: Nov
A14: 10001294 | B14: GH TIANGGE STALLS ELECTRICAL | C14: IO CAPEX | E14: 100731408 | F14: 133836.89 | I14: 0 | J14: S | K14: 21307111 | L14: Accrued Pay- Interco | M14: 7 | N14: =_xlfn.XLOOKUP(M14,$Q$3:$Q$14,$R$3:$R$14) -> Jul | Q14: 12 | R14: Dec
A15: 10001294 | B15: GH TIANGGE STALLS ELECTRICAL | C15: IO CAPEX | E15: 100731408 | F15: 54098.31 | I15: 0 | J15: S | K15: 21307111 | L15: Accrued Pay- Interco | M15: 7 | N15: =_xlfn.XLOOKUP(M15,$Q$3:$Q$14,$R$3:$R$14) -> Jul
A16: 10001294 | B16: GH TIANGGE STALLS ELECTRICAL | C16: IO CAPEX | E16: 100731408 | F16: 62859.59 | I16: 0 | J16: S | K16: 21307111 | L16: Accrued Pay- Interco | M16: 7 | N16: =_xlfn.XLOOKUP(M16,$Q$3:$Q$14,$R$3:$R$14) -> Jul
A17: 10001294 | B17: GH TIANGGE STALLS ELECTRICAL | C17: IO CAPEX | E17: 100731408 | F17: 111291.66 | I17: 0 | J17: S | K17: 21307111 | L17: Accrued Pay- Interco | M17: 7 | N17: =_xlfn.XLOOKUP(M17,$Q$3:$Q$14,$R$3:$R$14) -> Jul
A18: 10001294 | B18: GH TIANGGE STALLS ELECTRICAL | C18: IO CAPEX | E18: 100731408 | F18: 73621.39 | I18: 0 | J18: S | K18: 21307111 | L18: Accrued Pay- Interco | M18: 7 | N18: =_xlfn.XLOOKUP(M18,$Q$3:$Q$14,$R$3:$R$14) -> Jul
A19: 10001294 | B19: GH TIANGGE STALLS ELECTRICAL | C19: IO CAPEX | E19: 100731408 | F19: 98179.7 | I19: 0 | J19: S | K19: 21307111 | L19: Accrued Pay- Interco | M19: 7 | N19: =_xlfn.XLOOKUP(M19,$Q$3:$Q$14,$R$3:$R$14) -> Jul
A20: 10001294 | B20: GH TIANGGE STALLS ELECTRICAL | C20: IO CAPEX | E20: 100731408 | F20: 51090.77 | I20: 0 | J20: S | K20: 21307111 | L20: Accrued Pay- Interco | M20: 7 | N20: =_xlfn.XLOOKUP(M20,$Q$3:$Q$14,$R$3:$R$14) -> Jul
A21: 10001294 | B21: GH TIANGGE STALLS ELECTRICAL | C21: IO CAPEX | D21: 4500029617 | E21: 5000055775 | F21: 1134821.4 | G21: Electrical Provision for 427 Stalls | I21: 0.31 | J21: S | K21: 21301102 | L21: Trade A/P Clearing | M21: 4 | N21: =_xlfn.XLOOKUP(M21,$Q$3:$Q$14,$R$3:$R$14) -> Apr
A22: 10001294 | B22: GH TIANGGE STALLS ELECTRICAL | C22: IO CAPEX | D22: 4500029617 | E22: 5000055074 | F22: 2233035.7 | G22: Electrical Provision for 427 Stalls | I22: 0.61 | J22: S | K22: 21301102 | L22: Trade A/P Clearing | M22: 3 | N22: =_xlfn.XLOOKUP(M22,$Q$3:$Q$14,$R$3:$R$14) -> Mar
A23: 10001294 | B23: GH TIANGGE STALLS ELECTRICAL | C23: IO CAPEX | D23: 4500032689 | E23: 5000057548 | F23: 7875 | G23: UPS BATTERY 12V 7AH FOR UPS 650VA | I23: 9 | J23: S | K23: 21301102 | L23: Trade A/P Clearing | M23: 8 | N23: =_xlfn.XLOOKUP(M23,$Q$3:$Q$14,$R$3:$R$14) -> Aug
A24: 10001294 | B24: GH TIANGGE STALLS ELECTRICAL | C24: IO CAPEX | D24: 4500029617 | E24: 5000055492 | F24: -2233035.7 | G24: Electrical Provision for 427 Stalls | I24: -0.61 | J24: S | K24: 21301102 | L24: Trade A/P Clearing | M24: 4 | N24: =_xlfn.XLOOKUP(M24,$Q$3:$Q$14,$R$3:$R$14) -> Apr
A25: 10001294 | B25: GH TIANGGE STALLS ELECTRICAL | C25: IO CAPEX | D25: 4500029617 | E25: 5000055493 | F25: 2525892.9 | G25: Electrical Provision for 427 Stalls | I25: 0.69 | J25: S | K25: 21301102 | L25: Trade A/P Clearing | M25: 4 | N25: =_xlfn.XLOOKUP(M25,$Q$3:$Q$14,$R$3:$R$14) -> Apr
A26: 10001296 | B26: GH MALL ADMIN RELOCATION AND CONVERSION | C26: IO CAPEX | D26: 4500031193 | E26: 5000055010 | F26: 464285.71 | G26: ADDITIONAL WORKS AT GH ADMIN NEW OFFICE | I26: 1 | J26: S | K26: 21301102 | L26: Trade A/P Clearing | M26: 3 | N26: =_xlfn.XLOOKUP(M26,$Q$3:$Q$14,$R$3:$R$14) -> Mar
A27: 10001296 | B27: GH MALL ADMIN RELOCATION AND CONVERSION | C27: IO CAPEX | E27: 101668770 | F27: -197321.43 | I27: 0 | J27: S | K27: 52061103 | L27: DOE Rprs & Main-Bldg | M27: 2 | N27: =_xlfn.XLOOKUP(M27,$Q$3:$Q$14,$R$3:$R$14) -> Feb
A28: 10001296 | B28: GH MALL ADMIN RELOCATION AND CONVERSION | C28: IO CAPEX | D28: 4500027836 | E28: 5000054373 | F28: 169696.43 | G28: SUPPLY OF GRANDSTREAM IP PHONES DEVICES | I28: 0.86 | J28: S | K28: 21301102 | L28: Trade A/P Clearing | M28: 1 | N28: =_xlfn.XLOOKUP(M28,$Q$3:$Q$14,$R$3:$R$14) -> Jan
A29: 10001296 | B29: GH MALL ADMIN RELOCATION AND CONVERSION | C29: IO CAPEX | D29: 4500027836 | E29: 5000054747 | F29: -169696.43 | G29: SUPPLY OF GRANDSTREAM IP PHONES DEVICES | I29: -0.86 | J29: S | K29: 21301102 | L29: Trade A/P Clearing | M29: 2 | N29: =_xlfn.XLOOKUP(M29,$Q$3:$Q$14,$R$3:$R$14) -> Feb
A30: 10001296 | B30: GH MALL ADMIN RELOCATION AND CONVERSION | C30: IO CAPEX | D30: 4500027836 | E30: 5100047378 | F30: -26785.72 | G30: SUPPLY OF GRANDSTREAM IP PHONES DEVICES | H30: 4500027836 | I30: 0 | J30: S | K30: 21301102 | L30: Trade A/P Clearing | M30: 2 | N30: =_xlfn.XLOOKUP(M30,$Q$3:$Q$14,$R$3:$R$14) -> Feb
A31: 10001296 | B31: GH MALL ADMIN RELOCATION AND CONVERSION | C31: IO CAPEX | D31: 4500027836 | E31: 5000054748 | F31: 197321.43 | G31: SUPPLY OF GRANDSTREAM IP PHONES DEVICES | I31: 1 | J31: S | K31: 21301102 | L31: Trade A/P Clearing | M31: 2 | N31: =_xlfn.XLOOKUP(M31,$Q$3:$Q$14,$R$3:$R$14) -> Feb
A32: 10001298 | B32: CC DRAINAGE IMPROVEMENT PH1A | C32: IO CAPEX | E32: 1900352470 | F32: -0.01 | H32: PO#4500027421 | I32: 0 | J32: K | K32: 60000112 | L32: ADBASCO ENGINEERING WORKS AND | M32: 6 | N32: =_xlfn.XLOOKUP(M32,$Q$3:$Q$14,$R$3:$R$14) -> Jun
A33: 10001311 | B33: SC2&3 WATER PROOFING OF ROOF DECK FLOORI | C33: IO CAPEX | D33: 4500030775 | E33: 5000055255 | F33: 3161591.1 | G33: WATERPROOFING OF SC 2 (2,232.33sqm) | I33: 1 | J33: S | K33: 21301102 | L33: Trade A/P Clearing | M33: 3 | N33: =_xlfn.XLOOKUP(M33,$Q$3:$Q$14,$R$3:$R$14) -> Mar
A34: 10001314 | B34: GH TOWER BIR FIT-OUT | C34: IO CAPEX | D34: 4500030726 | E34: 5000055868 | F34: 42410.71 | G34: Solid Wood Top Mahogany | H34: BIR SAN JUAN-FB-AADD | I34: 1 | J34: S | K34: 21301102 | L34: Trade A/P Clearing | M34: 4 | N34: =_xlfn.XLOOKUP(M34,$Q$3:$Q$14,$R$3:$R$14) -> Apr
A35: 10001314 | B35: GH TOWER BIR FIT-OUT | C35: IO CAPEX | D35: 4500030726 | E35: 5000055867 | F35: 55803.57 | G35: Solid Wood Top Mahogany | H35: BIR SAN JUAN-FB-AADD | I35: 1 | J35: S | K35: 21301102 | L35: Trade A/P Clearing | M35: 4 | N35: =_xlfn.XLOOKUP(M35,$Q$3:$Q$14,$R$3:$R$14) -> Apr
A36: 10001314 | B36: GH TOWER BIR FIT-OUT | C36: IO CAPEX | D36: 4500030253 | E36: 5100047916 | F36: 0.01 | G36: 6-DOOR LOCKER | H36: 4500030253 | I36: 0 | J36: K | K36: 60003928 | L36: EXTENSIVE SALES ENTERPRISES COMPANY | M36: 3 | N36: =_xlfn.XLOOKUP(M36,$Q$3:$Q$14,$R$3:$R$14) -> Mar
A37: 10001314 | B37: GH TOWER BIR FIT-OUT | C37: IO CAPEX | D37: 4500030253 | E37: 5100047915 | F37: -0.01 | G37: 6-DOOR LOCKER | H37: 4500030253 | I37: 0 | J37: K | K37: 60003928 | L37: EXTENSIVE SALES ENTERPRISES COMPANY | M37: 3 | N37: =_xlfn.XLOOKUP(M37,$Q$3:$Q$14,$R$3:$R$14) -> Mar
A38: 10001314 | B38: GH TOWER BIR FIT-OUT | C38: IO CAPEX | D38: 4500032520 | E38: 5000057367 | F38: 53571.43 | G38: Supply of Imported Manual Curtain | H38: BIR SAN JUAN-FB-MCIP | I38: 1 | J38: S | K38: 21301102 | L38: Trade A/P Clearing | M38: 7 | N38: =_xlfn.XLOOKUP(M38,$Q$3:$Q$14,$R$3:$R$14) -> Jul
A39: 10001314 | B39: GH TOWER BIR FIT-OUT | C39: IO CAPEX | D39: 4500030726 | E39: 5100048423 | F39: 0.01 | G39: Solid Wood Top Mahogany | H39: 4500030726 | I39: 0 | J39: K | K39: 60002241 | L39: AADD OFFICE FURNITURE TRADING | M39: 4 | N39: =_xlfn.XLOOKUP(M39,$Q$3:$Q$14,$R$3:$R$14) -> Apr
A40: 10001314 | B40: GH TOWER BIR FIT-OUT | C40: IO CAPEX | D40: 4500030253 | E40: 5100047914 | F40: 0.01 | G40: 6-DOOR LOCKER | H40: 4500030253 | I40: 0 | J40: K | K40: 60003928 | L40: EXTENSIVE SALES ENTERPRISES COMPANY | M40: 3 | N40: =_xlfn.XLOOKUP(M40,$Q$3:$Q$14,$R$3:$R$14) -> Mar
...

Sheet Open PR PO
K1: =SUBTOTAL(9,K3:K1048576) -> 2.3412822e+08
A2: Order | B2: Cost element | C2: Company Code | D2: Document Date | E2: Debit date | F2: Reference document category | G2: Ref Document Number | H2: Name | I2: Total Quantity | J2: Unit of Measure | K2: Val.in rep.cur. | L2: Vendor | M2: User Name | N2: SBU
A3: 10000820 | B3: 78011101 | C3: 8000 | D3: 44483 | E3: 44497 | F3: POrd | G3: 4500016839 | H3: GH VMALL PARK DESIGN | I3: 0.35 | J3: LOT | K3: 278125 | L3: 60000389 | M3: LOPEZMV | N3: =_xlfn.XLOOKUP(A3,Monitoring!A:A,Monitoring!D:D) -> ESTATES
A4: 10001021 | B4: 78011101 | C4: 8000 | D4: 44776 | E4: 44790 | F4: POrd | G4: 4500019107 | H4: Utilities Relocation-Citiaire | I4: 0.157 | J4: LOT | K4: 3224107.1 | L4: 60000181 | M4: VIGALDF | N4: =_xlfn.XLOOKUP(A4,Monitoring!A:A,Monitoring!D:D) -> ESTATES
A5: 10001021 | B5: 78011101 | C5: 8000 | D5: 45847 | E5: 45861 | F5: POrd | G5: 4500028834 | H5: GH STREETSCAPING SIGNAGES | I5: 1 | J5: LOT | K5: 1160714.3 | L5: 60003122 | M5: CAMPONGSI | N5: =_xlfn.XLOOKUP(A5,Monitoring!A:A,Monitoring!D:D) -> ESTATES
A6: 10001021 | B6: 78011101 | C6: 8000 | D6: 45357 | E6: 45341 | F6: POrd | G6: 4500024077 | H6: S&I ELECTRICAL WORKS AT GH STREETSCAPE | I6: 0.1 | J6: LOT | K6: 441964.29 | L6: 60003331 | M6: VIGALDF | N6: =_xlfn.XLOOKUP(A6,Monitoring!A:A,Monitoring!D:D) -> ESTATES
A7: 10001021 | B7: 78011101 | C7: 8000 | D7: 44810 | E7: 44809 | F7: POrd | G7: 4500019418 | H7: Upon Project Completion | I7: 1 | J7: LOT | K7: 28839.29 | L7: 60002908 | M7: ABEJARND | N7: =_xlfn.XLOOKUP(A7,Monitoring!A:A,Monitoring!D:D) -> ESTATES
A8: 10001072 | B8: 78011101 | C8: 8100 | D8: 45159 | E8: 45163 | F8: POrd | G8: 4500022241 | H8: RECTIFICATION OF LEAK AT SHOPPESVILLE | I8: 1 | J8: LOT | K8: 142000 | L8: 60002847 | M8: AGUILARIB | N8: =_xlfn.XLOOKUP(A8,Monitoring!A:A,Monitoring!D:D) -> MALLS
A9: 10001134 | B9: 78011101 | C9: 8100 | D9: 45223 | E9: 45219 | F9: POrd | G9: 4500022912 | H9: EIFS DROPWALL | I9: 0.247 | J9: LOT | K9: 789517.86 | L9: 60003426 | M9: AP_OFC | N9: =_xlfn.XLOOKUP(A9,Monitoring!A:A,Monitoring!D:D) -> MALLS
A10: 10001136 | B10: 78011101 | C10: 8000 | D10: 45245 | E10: 46022 | F10: POrd | G10: 4500023106 | H10: Supply and installation of 4Units AC | I10: 0 | J10: LOT | K10: 0 | L10: 60000283 | M10: AP_RED | N10: =_xlfn.XLOOKUP(A10,Monitoring!A:A,Monitoring!D:D) -> RESIDENTIAL
A11: 10001140 | B11: 78011101 | C11: 8000 | D11: 45273 | E11: 45289 | F11: POrd | G11: 4500023470 | H11: AC DISMANTLING AND INSTALLATION WORKS | I11: 1 | J11: LOT | K11: 232142.86 | L11: 60002981 | M11: MAGABILINPR | N11: =_xlfn.XLOOKUP(A11,Monitoring!A:A,Monitoring!D:D) -> RESIDENTIAL
A12: 10001190 | B12: 78011101 | C12: 8100 | D12: 46006 | E12: 46022 | F12: POrd | G12: 4500030671 | H12: Rehabilitation of VRF at SC4 | I12: 0 | J12: LOT | K12: 0 | L12: 60003230 | M12: DEJORASTJO | N12: =_xlfn.XLOOKUP(A12,Monitoring!A:A,Monitoring!D:D) -> OFFICES
A13: 10001220 | B13: 78011101 | C13: 8000 | D13: 45790 | E13: 45790 | F13: POrd | G13: 4500028247 | H13: GH Estate Lift Station | I13: 0.02 | J13: LOT | K13: 99196.43 | L13: 60000181 | M13: DEJORASTJO | N13: =_xlfn.XLOOKUP(A13,Monitoring!A:A,Monitoring!D:D) -> ESTATES
A14: 10001254 | B14: 78011101 | C14: 8100 | D14: 45708 | E14: 45688 | F14: POrd | G14: 4500027401 | H14: S/S UTILITY & MOP SINK W/ FAUCET (PRIMY) | I14: 1 | J14: SET | K14: 23959.82 | L14: 60002230 | M14: CABATAYAD | N14: =_xlfn.XLOOKUP(A14,Monitoring!A:A,Monitoring!D:D) -> MALLS
... A25: 10001281 | B25: 78011101 | C25: 8100 | D25: 46049 | E25: 46112 | F25: POrd | G25: 4500030775 | H25: WATERPROOFING OF SC 2 (352.42sqm) | I25: 0 | J25: LOT | K25: 0 | L25: 60002847 | M25: DEJORASTJO | N25: =_xlfn.XLOOKUP(A25,Monitoring!A:A,Monitoring!D:D) -> OFFICES
A26: 10001281 | B26: 78011101 | C26: 8100 | D26: 46038 | E26: 46052 | F26: PReq | G26: 10032488 | H26: WATERPROOFING OF SC 2 | I26: 0 | J26: LOT | K26: 0 | M26: PANGANIBANCJ | N26: =_xlfn.XLOOKUP(A26,Monitoring!A:A,Monitoring!D:D) -> OFFICES
A27: 10001281 | B27: 78011101 | C27: 8100 | D27: 45806 | E27: 45900 | F27: POrd | G27: 4500028439 | H27: WATERPROOFING OF SC4 - 3,250 sq.m | I27: 0.28 | J27: LOT | K27: 1031737.5 | L27: 60003988 | M27: DEJORASTJO | N27: =_xlfn.XLOOKUP(A27,Monitoring!A:A,Monitoring!D:D) -> OFFICES
A28: 10001288 | B28: 78011101 | C28: 8100 | D28: 45973 | E28: 45961 | F28: POrd | G28: 4500030299 | H28: SUPPLY & INSTALLATION OF ISOLATOR SPRING | I28: 1 | J28: LOT | K28: 7500 | L28: 60003096 | M28: CABATAYAD | N28: =_xlfn.XLOOKUP(A28,Monitoring!A:A,Monitoring!D:D) -> MALLS
A29: 10001289 | B29: 78011101 | C29: 8100 | D29: 45796 | E29: 45808 | F29: POrd | G29: 4500028295 | H29: PROV.OF KITCHEN EXHAUST & FRESH AIR DUCT | I29: 1 | J29: LOT | K29: 42857.14 | L29: 60003096 | M29: CABATAYAD | N29: =_xlfn.XLOOKUP(A29,Monitoring!A:A,Monitoring!D:D) -> MALLS
A30: 10001294 | B30: 78011101 | C30: 8000 | D30: 46202 | E30: 46233 | F30: PReq | G30: 10034422 | H30: UPS BATTERY 12V 7AH FOR UPS 650VA | I30: 0 | J30: PC | K30: 0 | M30: CABATAYAD | N30: =_xlfn.XLOOKUP(A30,Monitoring!A:A,Monitoring!D:D) -> MALLS
A31: 10001294 | B31: 78011101 | C31: 8000 | D31: 46217 | E31: 46233 | F31: POrd | G31: 4500032689 | H31: UPS BATTERY 12V 7AH FOR UPS 650VA | I31: 0 | J31: PC | K31: 0 | L31: 60000772 | M31: ORLINAKC | N31: =_xlfn.XLOOKUP(A31,Monitoring!A:A,Monitoring!D:D) -> MALLS
A32: 10001294 | B32: 78011101 | C32: 8000 | D32: 45911 | E32: 45961 | F32: POrd | G32: 4500029617 | H32: Electrical Provision for 427 Stalls | I32: 0 | J32: LOT | K32: 0 | L32: 60003042 | M32: CAMPONGSI | N32: =_xlfn.XLOOKUP(A32,Monitoring!A:A,Monitoring!D:D) -> MALLS
A33: 10001296 | B33: 78011101 | C33: 8100 | D33: 45742 | E33: 45742 | F33: POrd | G33: 4500027836 | H33: SUPPLY OF GRANDSTREAM IP PHONES DEVICES | I33: 0 | J33: LOT | K33: 0 | L33: 60001016 | M33: CAMPONGSI | N33: =_xlfn.XLOOKUP(A33,Monitoring!A:A,Monitoring!D:D) -> MALLS
A34: 10001296 | B34: 78011101 | C34: 8100 | D34: 45742 | E34: 45742 | F34: POrd | G34: 4500027836 | H34: RELOCATION OF EXISTING PANASONIC | I34: 1 | J34: UNI | K34: 19754.46 | L34: 60001016 | M34: CABATAYAD | N34: =_xlfn.XLOOKUP(A34,Monitoring!A:A,Monitoring!D:D) -> MALLS
A35: 10001296 | B35: 78011101 | C35: 8100 | D35: 46079 | E35: 46093 | F35: PReq | G35: 10033015 | H35: ADDITIONAL WORKS AT GH ADMIN NEW OFFICE | I35: 0 | J35: LOT | K35: 0 | M35: PANGANIBANCJ | N35: =_xlfn.XLOOKUP(A35,Monitoring!A:A,Monitoring!D:D) -> MALLS
A36: 10001296 | B36: 78011101 | C36: 8100 | D36: 46080 | E36: 46093 | F36: POrd | G36: 4500031193 | H36: ADDITIONAL WORKS AT GH ADMIN NEW OFFICE | I36: 0 | J36: LOT | K36: 0 | L36: 60002747 | M36: CAMPONGSI | N36: =_xlfn.XLOOKUP(A36,Monitoring!A:A,Monitoring!D:D) -> MALLS
A37: 10001296 | B37: 78011101 | C37: 8100 | D37: 45875 | E37: 45883 | F37: POrd | G37: 4500029152 | H37: WILCON POZZI 959600000583 | I37: 1 | J37: SET | K37: 1055.86 | L37: 60001325 | M37: CABATAYAD | N37: =_xlfn.XLOOKUP(A37,Monitoring!A:A,Monitoring!D:D) -> MALLS
A38: 10001296 | B38: 78011101 | C38: 8100 | D38: 46076 | E38: 46090 | F38: PReq | G38: 10032960 | H38: ADDITIONAL WORKS AT NEW ADMIN OFFICE | I38: 0 | J38: LOT | K38: 0 | M38: CERTIFICOMDL | N38: =_xlfn.XLOOKUP(A38,Monitoring!A:A,Monitoring!D:D) -> MALLS
A39: 10001298 | B39: 78011101 | C39: 8000 | D39: 45792 | E39: 45797 | F39: POrd | G39: 4500028271 | H39: VERIFICATION AND AS-BUILT SURVEY | I39: 0.107 | J39: LOT | K39: 3595.2 | L39: 60003027 | M39: VIGALDF | N39: =_xlfn.XLOOKUP(A39,Monitoring!A:A,Monitoring!D:D) -> ESTATES
A40: 10001298 | B40: 78011101 | C40: 8000 | D40: 45792 | E40: 45797 | F40: POrd | G40: 4500028271 | H40: VERIFICATION AND AS-BUILT SURVEY | I40: 0.107 | J40: LOT | K40: 3595.2 | L40: 60003027 | M40: VIGALDF | N40: =_xlfn.XLOOKUP(A40,Monitoring!A:A,Monitoring!D:D) -> ESTATES
A41: 10001302 | B41: 78011101 | C41: 8100 | D41: 45757 | E41: 45763 | F41: POrd | G41: 4500028004 | H41: ADDITIONAL PROVISION OF COLD WATERLINE | I41: 1 | J41: LOT | K41: 42857.14 | L41: 60000181 | M41: CABATAYAD | N41: =_xlfn.XLOOKUP(A41,Monitoring!A:A,Monitoring!D:D) -> MALLS
A42: 10001302 | B42: 78011101 | C42: 8100 | D42: 45755 | E42: 45762 | F42: POrd | G42: 4500027972 | H42: ADDITIONAL ELECTRICAL WORKS AT TEPPANYA | I42: 1 | J42: LOT | K42: 62500 | L42: 60000349 | M42: MAGABILINPR | N42: =_xlfn.XLOOKUP(A42,Monitoring!A:A,Monitoring!D:D) -> MALLS
A43: 10001302 | B43: 78011101 | C43: 8100 | D43: 45968 | E43: 45991 | F43: PReq | G43: 10032052 | H43: SUPPLY & INSTALLATION OF POWER SUPPLY FO | I43: 1 | J43: LOT | K43: 173386.04 | M43: DAYMIELJMA | N43: =_xlfn.XLOOKUP(A43,Monitoring!A:A,Monitoring!D:D) -> MALLS
A44: 10001305 | B44: 78011101 | C44: 8100 | D44: 45744 | E44: 45751 | F44: POrd | G44: 4500027861 | H44: ACP Cladding on Column at GH Annex | I44: 0.57 | J44: LOT | K44: 356250 | L44: 60003343 | M44: CAMPONGSI | N44: =_xlfn.XLOOKUP(A44,Monitoring!A:A,Monitoring!D:D) -> MALLS
A45: 10001311 | B45: 78011101 | C45: 8100 | D45: 46049 | E45: 46112 | F45: POrd | G45: 4500030775 | H45: WATERPROOFING OF SC 2 (2,232.33sqm) | I45: 0 | J45: LOT | K45: 0 | L45: 60002847 | M45: DEJORASTJO | N45: =_xlfn.XLOOKUP(A45,Monitoring!A:A,Monitoring!D:D) -> OFFICES
A46: 10001311 | B46: 78011101 | C46: 8100 | D46: 46038 | E46: 46052 | F46: PReq | G46: 10032488 | H46: WATERPROOFING OF SC 2 | I46: 0 | J46: LOT | K46: 0 | M46: PANGANIBANCJ | N46: =_xlfn.XLOOKUP(A46,Monitoring!A:A,Monitoring!D:D) -> OFFICES
A47: 10001311 | B47: 78011101 | C47: 8100 | D47: 45806 | E47: 45900 | F47: POrd | G47: 4500028439 | H47: WATERPROOFING OF SC2 - 2,584.75 sq.m | I47: 1 | J47: LOT | K47: 499123.19 | L47: 60003988 | M47: PANGANIBANCJ | N47: =_xlfn.XLOOKUP(A47,Monitoring!A:A,Monitoring!D:D) -> OFFICES
A48: 10001312 | B48: 78011101 | C48: 8100 | D48: 45783 | E48: 45777 | F48: POrd | G48: 4500028207 | H48: S&I OF CONFESSION ROOM DIVIDER | I48: 1 | J48: LOT | K48: 12232.14 | L48: 60002670 | M48: CABATAYAD | N48: =_xlfn.XLOOKUP(A48,Monitoring!A:A,Monitoring!D:D) -> MALLS
A49: 10001314 | B49: 78011101 | C49: 8100 | D49: 46041 | E49: 46041 | F49: POrd | G49: 4500030726 | H49: Solid Wood Top Mahogany | I49: 0 | J49: SET | K49: 0 | L49: 60002241 | M49: VIGALDF | N49: =_xlfn.XLOOKUP(A49,Monitoring!A:A,Monitoring!D:D) -> OFFICES
A50: 10001314 | B50: 78011101 | C50: 8100 | D50: 46041 | E50: 46031 | F50: POrd | G50: 4500030726 | H50: Solid Wood Top Mahogany | I50: 0 | J50: SET | K50: 0 | L50: 60002241 | M50: VIGALDF | N50: =_xlfn.XLOOKUP(A50,Monitoring!A:A,Monitoring!D:D) -> OFFICES
...

Sheet Monitoring
A1: Ortigas Land Corporation
A2: NPC List
A3: December 31, 2026
A4: Sep | Z4: =Z5-'SAP Report'!C2 -> 2041964.3 | AA4: =AA5-'SAP Report'!D2 -> 0 | AB4: =AB5-'SAP Report'!E2 -> 0 | AC4: =AC5-'SAP Report'!F2 -> 0 | AD4: =AD5-'SAP Report'!G2 -> 2041964.3 | AG4: Monthly Forecast | AV4: YTD Forecast
R5: =SUBTOTAL(9,R7:R1048576) -> 7.1059177e+08 | Z5: =SUBTOTAL(9,Z7:Z1048576) -> 7.0971022e+08 | AA5: =SUBTOTAL(9,AA7:AA1048576) -> 1.5488819e+08 | AB5: =SUBTOTAL(9,AB7:AB1048576) -> 234128221 | AC5: =SUBTOTAL(9,AC7:AC1048576) -> 3.8901642e+08 | AD5: =SUBTOTAL(9,AD7:AD1048576) -> 3.2069381e+08 | AE5: =SUBTOTAL(9,AE7:AE1048576) -> 5.5482203e+08 | AG5: =SUBTOTAL(9,AG7:AG1048576) -> 5254631.9 | AH5: =SUBTOTAL(9,AH7:AH1048576) -> 15242658 | AI5: =SUBTOTAL(9,AI7:AI1048576) -> 20216894 | AJ5: =SUBTOTAL(9,AJ7:AJ1048576) -> 23144199 | AK5: =SUBTOTAL(9,AK7:AK1048576) -> 24344173 | AL5: =SUBTOTAL(9,AL7:AL1048576) -> 19564399 | AM5: =SUBTOTAL(9,AM7:AM1048576) -> 18820099 | AN5: =SUBTOTAL(9,AN7:AN1048576) -> 18255306 | ... AT5: =SUBTOTAL(9,AT7:AT1048576) -> 0 | AV5: =SUBTOTAL(9,AV7:AV1048576) -> 5254631.9 | AW5: =SUBTOTAL(9,AW7:AW1048576) -> 20497290 | AX5: =SUBTOTAL(9,AX7:AX1048576) -> 40714184 | AY5: =SUBTOTAL(9,AY7:AY1048576) -> 63858382 | AZ5: =SUBTOTAL(9,AZ7:AZ1048576) -> 88202556 | BA5: =SUBTOTAL(9,BA7:BA1048576) -> 1.0776695e+08 | BB5: =SUBTOTAL(9,BB7:BB1048576) -> 1.2658705e+08 | BC5: =SUBTOTAL(9,BC7:BC1048576) -> 1.4484236e+08 | ... BG5: =SUBTOTAL(9,BG7:BG1048576) -> 7.0971022e+08
A6: Orders | B6: IO Description | C6: SBU | D6: SBU2 | E6: Group | F6: Special Project? | G6: Type | H6: Budget Source Code | I6: Order Type | J6: PROJECT NAME | K6: Count | L6: Co. Code | M6: CC NUMBERS | N6: CC NAME | O6: APPLICANT | P6: PERSON RESPONSIBLE | Q6: BPM Ticket No. | R6: Amount | S6: APPLICATION DATE | T6: DIVISION | U6: START OF PROJECT | V6: END OF PROJECT | W6: Date processed | X6: SAP Doc. No. | Z6: Budget | AA6: Actual | AB6: Committed (open PRPO) | AC6: Allotted | AD6: Available1 | AE6: Available2 | AG6: Jan | AH6: Feb | AI6: Mar | AJ6: Apr | AK6: May | AL6: Jun | AM6: Jul | AN6: Aug | AO6: Sep | AP6: Oct | AQ6: Nov | AR6: Dec | AS6: Total | AT6: Balance | AV6: Jan | AW6: Feb | AX6: Mar | AY6: Apr | AZ6: May | BA6: Jun | BB6: Jul | BC6: Aug | BD6: Sep | BE6: Oct | BF6: Nov | BG6: Dec
A7: 10001072 | B7: GH RFDCK/CNOPIES/PRMTR WALL | C7: MALLS | D7: MALLS | F7: N | G7: Carry-over | R7: =_xlfn.XLOOKUP(A7,Malls!B:B,Malls!G:G) -> 142000 | T7: =_xlfn.XLOOKUP(M7,[1]Sheet1!$A:$A,[1]Sheet1!$E:$E) -> 0 | Z7: =_xlfn.XLOOKUP(A7,'SAP Report'!A:A,'SAP Report'!C:C) -> 142000 | AA7: =HLOOKUP($A$4,$AV$6:$BG7,2,FALSE) -> 0 | AB7: =SUMIF('Open PR PO'!A:A,Monitoring!A7,'Open PR PO'!K:K) -> 142000 | AC7: =AA7+AB7 -> 142000 | AD7: =Z7-AC7 -> 0 | AE7: =Z7-AA7 -> 142000 | AG7: =SUMIFS(Actual!$F:$F,Actual!$N:$N,Monitoring!AG$6,Actual!$A:$A,Monitoring!$A7) -> 0 | AH7: =SUMIFS(Actual!$F:$F,Actual!$N:$N,Monitoring!AH$6,Actual!$A:$A,Monitoring!$A7) -> 0 | AI7: =SUMIFS(Actual!$F:$F,Actual!$N:$N,Monitoring!AI$6,Actual!$A:$A,Monitoring!$A7) -> 0 | AJ7: =SUMIFS(Actual!$F:$F,Actual!$N:$N,Monitoring!AJ$6,Actual!$A:$A,Monitoring!$A7) -> 0 | AK7: =SUMIFS(Actual!$F:$F,Actual!$N:$N,Monitoring!AK$6,Actual!$A:$A,Monitoring!$A7) -> 0 | AL7: =SUMIFS(Actual!$F:$F,Actual!$N:$N,Monitoring!AL$6,Actual!$A:$A,Monitoring!$A7) -> 0 | AM7: =SUMIFS(Actual!$F:$F,Actual!$N:$N,Monitoring!AM$6,Actual!$A:$A,Monitoring!$A7) -> 0 | AN7: =SUMIFS(Actual!$F:$F,Actual!$N:$N,Monitoring!AN$6,Actual!$A:$A,Monitoring!$A7) -> 0 | AO7: =SUMIFS(Actual!$F:$F,Actual!$N:$N,Monitoring!AO$6,Actual!$A:$A,Monitoring!$A7) -> 0 | AP7: =AB7 -> 142000 | AQ7: =AD7/2 -> 0 | AR7: =AQ7 -> 0 | AS7: =SUM(AG7:AR7) -> 142000 | AT7: =Z7-AS7 -> 0 | AV7: =AG7 -> 0 | AW7: =AV7+AH7 -> 0 | AX7: =AW7+AI7 -> 0 | AY7: =AX7+AJ7 -> 0 | AZ7: =AY7+AK7 -> 0 | BA7: =AZ7+AL7 -> 0 | BB7: =BA7+AM7 -> 0 | BC7: =BB7+AN7 -> 0 | BD7: =BC7+AO7 -> 0 | ... BG7: =BF7+AR7 -> 142000 | BH7: 1
A8: 10001134 | B8: GH TIANGGE EIFS DROPWALL | C8: MALLS | D8: MALLS | F8: N | G8: Carry-over | R8: =_xlfn.XLOOKUP(A8,Malls!B:B,Malls!G:G) -> 789517.86 | T8: =_xlfn.XLOOKUP(M8,[1]Sheet1!$A:$A,[1]Sheet1!$E:$E) -> 0 | Z8: =_xlfn.XLOOKUP(A8,'SAP Report'!A:A,'SAP Report'!C:C) -> 789517.86 | AA8: =HLOOKUP($A$4,$AV$6:$BG8,(2+BH7),FALSE) -> 0 | AB8: =SUMIF('Open PR PO'!A:A,Monitoring!A8,'Open PR PO'!K:K) -> 789517.86 | AC8: =AA8+AB8 -> 789517.86 | AD8: =Z8-AC8 -> 0 | AE8: =Z8-AA8 -> 789517.86 | AG8: =SUMIFS(Actual!$F:$F,Actual!$N:$N,Monitoring!AG$6,Actual!$A:$A,Monitoring!$A8) -> 0 | AH8: =SUMIFS(Actual!$F:$F,Actual!$N:$N,Monitoring!AH$6,Actual!$A:$A,Monitoring!$A8) -> 0 | AI8: =SUMIFS(Actual!$F:$F,Actual!$N:$N,Monitoring!AI$6,Actual!$A:$A,Monitoring!$A8) -> 0 | AJ8: =SUMIFS(Actual!$F:$F,Actual!$N:$N,Monitoring!AJ$6,Actual!$A:$A,Monitoring!$A8) -> 0 | AK8: =SUMIFS(Actual!$F:$F,Actual!$N:$N,Monitoring!AK$6,Actual!$A:$A,Monitoring!$A8) -> 0 | AL8: =SUMIFS(Actual!$F:$F,Actual!$N:$N,Monitoring!AL$6,Actual!$A:$A,Monitoring!$A8) -> 0 | AM8: =SUMIFS(Actual!$F:$F,Actual!$N:$N,Monitoring!AM$6,Actual!$A:$A,Monitoring!$A8) -> 0 | AN8: =SUMIFS(Actual!$F:$F,Actual!$N:$N,Monitoring!AN$6,Actual!$A:$A,Monitoring!$A8) -> 0 | AO8: =SUMIFS(Actual!$F:$F,Actual!$N:$N,Monitoring!AO$6,Actual!$A:$A,Monitoring!$A8) -> 0 | AP8: =AB8 -> 789517.86 | AQ8: =AD8/2 -> 0 | AR8: =AQ8 -> 0 | AS8: =SUM(AG8:AR8) -> 789517.86 | AT8: =Z8-AS8 -> 0 | AV8: =AG8 -> 0 | AW8: =AV8+AH8 -> 0 | AX8: =AW8+AI8 -> 0 | AY8: =AX8+AJ8 -> 0 | AZ8: =AY8+AK8 -> 0 | BA8: =AZ8+AL8 -> 0 | BB8: =BA8+AM8 -> 0 | BC8: =BB8+AN8 -> 0 | BD8: =BC8+AO8 -> 0 | ... BG8: =BF8+AR8 -> 789517.86 | BH8: =BH7+1 -> 2
A9: 10001262 | B9: GH NEW MALL REWATERPROOFING | C9: MALLS | D9: MALLS | F9: N | G9: Carry-over | R9: =_xlfn.XLOOKUP(A9,Malls!B:B,Malls!G:G) -> 767321.42 | T9: =_xlfn.XLOOKUP(M9,[1]Sheet1!$A:$A,[1]Sheet1!$E:$E) -> 0 | Z9: =_xlfn.XLOOKUP(A9,'SAP Report'!A:A,'SAP Report'!C:C) -> 767321.43 | AA9: =HLOOKUP($A$4,$AV$6:$BG9,(2+BH8),FALSE) -> 417857.14 | AB9: =SUMIF('Open PR PO'!A:A,Monitoring!A9,'Open PR PO'!K:K) -> 349464.28 | AC9: =AA9+AB9 -> 767321.42 | AD9: =Z9-AC9 -> 0.01 | AE9: =Z9-AA9 -> 349464.29 | AG9: =SUMIFS(Actual!$F:$F,Actual!$N:$N,Monitoring!AG$6,Actual!$A:$A,Monitoring!$A9) -> 0 | AH9: =SUMIFS(Actual!$F:$F,Actual!$N:$N,Monitoring!AH$6,Actual!$A:$A,Monitoring!$A9) -> 0 | AI9: =SUMIFS(Actual!$F:$F,Actual!$N:$N,Monitoring!AI$6,Actual!$A:$A,Monitoring!$A9) -> 0 | AJ9: =SUMIFS(Actual!$F:$F,Actual!$N:$N,Monitoring!AJ$6,Actual!$A:$A,Monitoring!$A9) -> 417857.14 | AK9: =SUMIFS(Actual!$F:$F,Actual!$N:$N,Monitoring!AK$6,Actual!$A:$A,Monitoring!$A9) -> 0 | AL9: =SUMIFS(Actual!$F:$F,Actual!$N:$N,Monitoring!AL$6,Actual!$A:$A,Monitoring!$A9) -> 0 | AM9: =SUMIFS(Actual!$F:$F,Actual!$N:$N,Monitoring!AM$6,Actual!$A:$A,Monitoring!$A9) -> 0 | AN9: =SUMIFS(Actual!$F:$F,Actual!$N:$N,Monitoring!AN$6,Actual!$A:$A,Monitoring!$A9) -> 0 | AO9: =SUMIFS(Actual!$F:$F,Actual!$N:$N,Monitoring!AO$6,Actual!$A:$A,Monitoring!$A9) -> 0 | AP9: =AB9 -> 349464.28 | AQ9: =AD9/2 -> 0.005 | AR9: =AQ9 -> 0.005 | AS9: =SUM(AG9:AR9) -> 767321.43 | AT9: =Z9-AS9 -> 0 | AV9: =AG9 -> 0 | AW9: =AV9+AH9 -> 0 | AX9: =AW9+AI9 -> 0 | AY9: =AX9+AJ9 -> 417857.14 | AZ9: =AY9+AK9 -> 417857.14 | BA9: =AZ9+AL9 -> 417857.14 | BB9: =BA9+AM9 -> 417857.14 | BC9: =BB9+AN9 -> 417857.14 | BD9: =BC9+AO9 -> 417857.14 | ... BG9: =BF9+AR9 -> 767321.43 | BH9: =BH8+1 -> 3
A10: 10001254 | B10: ES CONSTRUCTION OF OMD ADMIN | C10: MALLS | D10: MALLS | F10: N | G10: Carry-over | R10: =_xlfn.XLOOKUP(A10,Malls!B:B,Malls!G:G) -> 32193.08 | T10: =_xlfn.XLOOKUP(M10,[1]Sheet1!$A:$A,[1]Sheet1!$E:$E) -> 0 | Z10: =_xlfn.XLOOKUP(A10,'SAP Report'!A:A,'SAP Report'!C:C) -> 32193.08 | AA10: =HLOOKUP($A$4,$AV$6:$BG10,(2+BH9),FALSE) -> 0 | AB10: =SUMIF('Open PR PO'!A:A,Monitoring!A10,'Open PR PO'!K:K) -> 32193.08 | AC10: =AA10+AB10 -> 32193.08 | AD10: =Z10-AC10 -> 0 | AE10: =Z10-AA10 -> 32193.08 | AG10: =SUMIFS(Actual!$F:$F,Actual!$N:$N,Monitoring!AG$6,Actual!$A:$A,Monitoring!$A10) -> 0 | AH10: =SUMIFS(Actual!$F:$F,Actual!$N:$N,Monitoring!AH$6,Actual!$A:$A,Monitoring!$A10) -> 0 | AI10: =SUMIFS(Actual!$F:$F,Actual!$N:$N,Monitoring!AI$6,Actual!$A:$A,Monitoring!$A10) -> 0 | AJ10: =SUMIFS(Actual!$F:$F,Actual!$N:$N,Monitoring!AJ$6,Actual!$A:$A,Monitoring!$A10) -> 0 | AK10: =SUMIFS(Actual!$F:$F,Actual!$N:$N,Monitoring!AK$6,Actual!$A:$A,Monitoring!$A10) -> 0 | AL10: =SUMIFS(Actual!$F:$F,Actual!$N:$N,Monitoring!AL$6,Actual!$A:$A,Monitoring!$A10) -> 0 | AM10: =SUMIFS(Actual!$F:$F,Actual!$N:$N,Monitoring!AM$6,Actual!$A:$A,Monitoring!$A10) -> 0 | AN10: =SUMIFS(Actual!$F:$F,Actual!$N:$N,Monitoring!AN$6,Actual!$A:$A,Monitoring!$A10) -> 0 | AO10: =SUMIFS(Actual!$F:$F,Actual!$N:$N,Monitoring!AO$6,Actual!$A:$A,Monitoring!$A10) -> 0 | AP10: =AB10 -> 32193.08 | AQ10: =AD10/2 -> 0 | AR10: =AQ10 -> 0 | AS10: =SUM(AG10:AR10) -> 32193.08 | AT10: =Z10-AS10 -> 0 | AV10: =AG10 -> 0 | AW10: =AV10+AH10 -> 0 | AX10: =AW10+AI10 -> 0 | AY10: =AX10+AJ10 -> 0 | AZ10: =AY10+AK10 -> 0 | BA10: =AZ10+AL10 -> 0 | BB10: =BA10+AM10 -> 0 | BC10: =BB10+AN10 -> 0 | BD10: =BC10+AO10 -> 0 | ... BG10: =BF10+AR10 -> 32193.08 | BH10: =BH9+1 -> 4
A11: 10001288 | B11: ES EAST WING 2024 SPACE RE-C | C11: MALLS | D11: MALLS | F11: N | G11: Carry-over | R11: =_xlfn.XLOOKUP(A11,Malls!B:B,Malls!G:G) -> 7500 | T11: =_xlfn.XLOOKUP(M11,[1]Sheet1!$A:$A,[1]Sheet1!$E:$E) -> 0 | Z11: =_xlfn.XLOOKUP(A11,'SAP Report'!A:A,'SAP Report'!C:C) -> 7500 | AA11: =HLOOKUP($A$4,$AV$6:$BG11,(2+BH10),FALSE) -> 0 | AB11: =SUMIF('Open PR PO'!A:A,Monitoring!A11,'Open PR PO'!K:K) -> 7500 | AC11: =AA11+AB11 -> 7500 | AD11: =Z11-AC11 -> 0 | AE11: =Z11-AA11 -> 7500 | AG11: =SUMIFS(Actual!$F:$F,Actual!$N:$N,Monitoring!AG$6,Actual!$A:$A,Monitoring!$A11) -> 0 | AH11: =SUMIFS(Actual!$F:$F,Actual!$N:$N,Monitoring!AH$6,Actual!$A:$A,Monitoring!$A11) -> 0 | AI11: =SUMIFS(Actual!$F:$F,Actual!$N:$N,Monitoring!AI$6,Actual!$A:$A,Monitoring!$A11) -> 0 | AJ11: =SUMIFS(Actual!$F:$F,Actual!$N:$N,Monitoring!AJ$6,Actual!$A:$A,Monitoring!$A11) -> 0 | AK11: =SUMIFS(Actual!$F:$F,Actual!$N:$N,Monitoring!AK$6,Actual!$A:$A,Monitoring!$A11) -> 0 | AL11: =SUMIFS(Actual!$F:$F,Actual!$N:$N,Monitoring!AL$6,Actual!$A:$A,Monitoring!$A11) -> 0 | AM11: =SUMIFS(Actual!$F:$F,Actual!$N:$N,Monitoring!AM$6,Actual!$A:$A,Monitoring!$A11) -> 0 | AN11: =SUMIFS(Actual!$F:$F,Actual!$N:$N,Monitoring!AN$6,Actual!$A:$A,Monitoring!$A11) -> 0 | AO11: =SUMIFS(Actual!$F:$F,Actual!$N:$N,Monitoring!AO$6,Actual!$A:$A,Monitoring!$A11) -> 0 | AP11: =AB11 -> 7500 | AQ11: =AD11/2 -> 0 | AR11: =AQ11 -> 0 | AS11: =SUM(AG11:AR11) -> 7500 | AT11: =Z11-AS11 -> 0 | AV11: =AG11 -> 0 | AW11: =AV11+AH11 -> 0 | AX11: =AW11+AI11 -> 0 | AY11: =AX11+AJ11 -> 0 | AZ11: =AY11+AK11 -> 0 | BA11: =AZ11+AL11 -> 0 | BB11: =BA11+AM11 -> 0 | BC11: =BB11+AN11 -> 0 | BD11: =BC11+AO11 -> 0 | ... BG11: =BF11+AR11 -> 7500 | BH11: =BH10+1 -> 5
A12: 10001289 | B12: ES MAIN 2025 SPACE RE-CUT & | C12: MALLS | D12: MALLS | F12: N | G12: Carry-over | R12: =_xlfn.XLOOKUP(A12,Malls!B:B,Malls!G:G) -> 42857.14 | T12: =_xlfn.XLOOKUP(M12,[1]Sheet1!$A:$A,[1]Sheet1!$E:$E) -> 0 | Z12: =_xlfn.XLOOKUP(A12,'SAP Report'!A:A,'SAP Report'!C:C) -> 42857.14 | AA12: =HLOOKUP($A$4,$AV$6:$BG12,(2+BH11),FALSE) -> 0 | AB12: =SUMIF('Open PR PO'!A:A,Monitoring!A12,'Open PR PO'!K:K) -> 42857.14 | AC12: =AA12+AB12 -> 42857.14 | AD12: =Z12-AC12 -> 0 | AE12: =Z12-AA12 -> 42857.14 | AG12: =SUMIFS(Actual!$F:$F,Actual!$N:$N,Monitoring!AG$6,Actual!$A:$A,Monitoring!$A12) -> 0 | AH12: =SUMIFS(Actual!$F:$F,Actual!$N:$N,Monitoring!AH$6,Actual!$A:$A,Monitoring!$A12) -> 0 | AI12: =SUMIFS(Actual!$F:$F,Actual!$N:$N,Monitoring!AI$6,Actual!$A:$A,Monitoring!$A12) -> 0 | AJ12: =SUMIFS(Actual!$F:$F,Actual!$N:$N,Monitoring!AJ$6,Actual!$A:$A,Monitoring!$A12) -> 0 | AK12: =SUMIFS(Actual!$F:$F,Actual!$N:$N,Monitoring!AK$6,Actual!$A:$A,Monitoring!$A12) -> 0 | AL12: =SUMIFS(Actual!$F:$F,Actual!$N:$N,Monitoring!AL$6,Actual!$A:$A,Monitoring!$A12) -> 0 | AM12: =SUMIFS(Actual!$F:$F,Actual!$N:$N,Monitoring!AM$6,Actual!$A:$A,Monitoring!$A12) -> 0 | AN12: =SUMIFS(Actual!$F:$F,Actual!$N:$N,Monitoring!AN$6,Actual!$A:$A,Monitoring!$A12) -> 0 | AO12: =SUMIFS(Actual!$F:$F,Actual!$N:$N,Monitoring!AO$6,Actual!$A:$A,Monitoring!$A12) -> 0 | AP12: =AB12 -> 42857.14 | AQ12: =AD12/2 -> 0 | AR12: =AQ12 -> 0 | AS12: =SUM(AG12:AR12) -> 42857.14 | AT12: =Z12-AS12 -> 0 | AV12: =AG12 -> 0 | AW12: =AV12+AH12 -> 0 | AX12: =AW12+AI12 -> 0 | AY12: =AX12+AJ12 -> 0 | AZ12: =AY12+AK12 -> 0 | BA12: =AZ12+AL12 -> 0 | BB12: =BA12+AM12 -> 0 | BC12: =BB12+AN12 -> 0 | BD12: =BC12+AO12 -> 0 | ... BG12: =BF12+AR12 -> 42857.14 | BH12: =BH11+1 -> 6
