Workbook

Sheet GAE
E1: Dropdown list | F1: Dropdown list | G1: Dropdown list | L1: Automatic | M1: Automatic
A2: CD | B2: YY | C2: Num | D2: Budget Code | E2: Expense Category | F2: Expense Line Item | G2: Company | H2: Description | I2: Department | J2: Centralized Dept Requestor/Reviewer | K2: Centralized Dept Head | L2: Cost Center (CC) | M2: GL Account (GL) | N2: Additional Field (required) | O2: Spend Grid Computation | P2: Spend Grid Frequency | Q2: Sample charges | R2: Visible only to (Department)
A3: =_xlfn.XLOOKUP(I3,Lookup!A:A,Lookup!B:B) -> AS | B3: 27 | C3: 1 | D3: =A3&-B3&-C3 -> AS-27-1 | E3: Admin Staff | F3: Company Driver | I3: Administrative Services | J3: Carolina C. Tenedero | K3: Carolina C. Tenedero | L3: 81123102 | M3: 52041499 | N3: Headcount, Rate per Month (w/ OT) | O3: Headcount x Rate per Month (w/ OT) | P3: Monthly | R3: Admin Services
A4: =_xlfn.XLOOKUP(I4,Lookup!A:A,Lookup!B:B) -> AS | B4: 27 | C4: =C3+1 -> 2 | D4: =A4&-B4&-C4 -> AS-27-2 | E4: Admin Staff | F4: Messenger | I4: Administrative Services | J4: Carolina C. Tenedero | K4: Carolina C. Tenedero | L4: 81123102 | M4: 52041499 | N4: Headcount, Rate per Month (w/ OT) | O4: Headcount x Rate per Month (w/ OT) | P4: Monthly | R4: Admin Services
A5: =_xlfn.XLOOKUP(I5,Lookup!A:A,Lookup!B:B) -> AS | B5: 27 | C5: =C4+1 -> 3 | D5: =A5&-B5&-C5 -> AS-27-3 | E5: Admin Staff | F5: Operator | I5: Administrative Services | J5: Carolina C. Tenedero | K5: Carolina C. Tenedero | L5: 81123102 | M5: 52041499 | N5: Headcount, Rate per Month (w/ OT) | O5: Headcount x Rate per Month (w/ OT) | P5: Monthly | R5: Admin Services
A6: =_xlfn.XLOOKUP(I6,Lookup!A:A,Lookup!B:B) -> AS | B6: 27 | C6: =C5+1 -> 4 | D6: =A6&-B6&-C6 -> AS-27-4 | E6: Communication | F6: Mobile Phone | G6: OCC | I6: Administrative Services | J6: Benedict Nicholas A. Sandejas | K6: Benedict Nicholas A. Sandejas | L6: 81123102 | M6: 52951101 | N6: Rank, Month Start, Employee Name, Department | P6: User to select which month
A7: =_xlfn.XLOOKUP(I7,Lookup!A:A,Lookup!B:B) -> AS | B7: 27 | C7: =C6+1 -> 5 | D7: =A7&-B7&-C7 -> AS-27-5 | E7: Communication | F7: Mobile Phone | G7: OCLP | I7: Administrative Services | J7: Benedict Nicholas A. Sandejas | K7: Benedict Nicholas A. Sandejas | L7: 80123102 | M7: 61721101 | N7: Rank, Month Start, Employee Name, Department | P7: User to select which month
A8: =_xlfn.XLOOKUP(I8,Lookup!A:A,Lookup!B:B) -> AS | B8: 27 | C8: =C7+1 -> 6 | D8: =A8&-B8&-C8 -> AS-27-6 | E8: Communication | F8: Phone - JHJ | I8: Administrative Services | J8: Benedict Nicholas A. Sandejas | K8: Benedict Nicholas A. Sandejas | L8: 80123102 | M8: 61721101
A9: =_xlfn.XLOOKUP(I9,Lookup!A:A,Lookup!B:B) -> AS | B9: 27 | C9: =C8+1 -> 7 | D9: =A9&-B9&-C9 -> AS-27-7 | E9: Communication | F9: Phone - MDIA | I9: Administrative Services | J9: Benedict Nicholas A. Sandejas | K9: Benedict Nicholas A. Sandejas | L9: 80123102 | M9: 61721101
A10: =_xlfn.XLOOKUP(I10,Lookup!A:A,Lookup!B:B) -> AS | B10: 27 | C10: =C9+1 -> 8 | D10: =A10&-B10&-C10 -> AS-27-8 | E10: Communication | F10: Trunk Line/Direct Line/Land Line | I10: Administrative Services | J10: Benedict Nicholas A. Sandejas | K10: Benedict Nicholas A. Sandejas | L10: 80123102 | M10: 61721101 | N10: Count | R10: Admin Services
A11: =_xlfn.XLOOKUP(I11,Lookup!A:A,Lookup!B:B) -> AS | B11: 27 | C11: =C10+1 -> 9 | D11: =A11&-B11&-C11 -> AS-27-9 | E11: Drivers' Meal Allowance | F11: Drivers' Meal Allowance | I11: Administrative Services | J11: Carolina C. Tenedero | K11: Carolina C. Tenedero | L11: 81123102 | M11: 52081103 | N11: Headcount, Meal Allowance Rate | O11: Headcount x Meal Allowance Rate x 20 days per month | P11: Monthly | R11: Admin Services
A12: =_xlfn.XLOOKUP(I12,Lookup!A:A,Lookup!B:B) -> AS | B12: 27 | C12: =C11+1 -> 10 | D12: =A12&-B12&-C12 -> AS-27-10 | E12: Dues and Fees | F12: Cenro | I12: Administrative Services | J12: Lino P. Arboleda | K12: Lino P. Arboleda | L12: 80123102 | M12: 61711101 | R12: Admin Services
A13: =_xlfn.XLOOKUP(I13,Lookup!A:A,Lookup!B:B) -> AS | B13: 27 | C13: =C12+1 -> 11 | D13: =A13&-B13&-C13 -> AS-27-11 | E13: Dues and Fees | F13: Others | I13: Administrative Services | J13: Lino P. Arboleda | K13: Lino P. Arboleda | L13: 80123102 | M13: 61711101 | N13: Specify | R13: Admin Services
A14: =_xlfn.XLOOKUP(I14,Lookup!A:A,Lookup!B:B) -> AS | B14: 27 | C14: =C13+1 -> 12 | D14: =A14&-B14&-C14 -> AS-27-12 | E14: Electricity & Water | F14: Electricity & Water | I14: Administrative Services | J14: Princess Vera P. Jumalon | K14: Princess Vera P. Jumalon | L14: 80123102 | M14: 61041101 | R14: TSG
A15: =_xlfn.XLOOKUP(I15,Lookup!A:A,Lookup!B:B) -> AS | B15: 27 | C15: =C14+1 -> 13 | D15: =A15&-B15&-C15 -> AS-27-13 | E15: Fuel & Lubricants | F15: Fuel & Lubricants - Fleet | I15: Administrative Services | J15: Carolina C. Tenedero | K15: Carolina C. Tenedero | L15: 80123102 | M15: 61111201 | R15: Admin Services
A16: =_xlfn.XLOOKUP(I16,Lookup!A:A,Lookup!B:B) -> AS | B16: 27 | C16: =C15+1 -> 14 | D16: =A16&-B16&-C16 -> AS-27-14 | E16: Fuel & Lubricants | F16: Fuel & Lubricants - Messenger | I16: Administrative Services | J16: Carolina C. Tenedero | K16: Carolina C. Tenedero | L16: 81123102 | M16: 52119101 | N16: Fuel Price per Liter, Average Daily Distance per Motor (km), Count of Motor | O16: ((Average Daily Distance km / 40km/L) x Fuel Price per Liter) x Count of Motor x 20 days per month | P16: Monthly | R16: Admin Services
A17: =_xlfn.XLOOKUP(I17,Lookup!A:A,Lookup!B:B) -> AS | B17: 27 | C17: =C16+1 -> 15 | D17: =A17&-B17&-C17 -> AS-27-15 | E17: Janitorial | F17: Janitorial | I17: Administrative Services | J17: Carolina C. Tenedero | K17: Carolina C. Tenedero | L17: 81123102 | M17: 52041405 | N17: Headcount, Rate per Month (w/ OT) | O17: Headcount x Rate per Month (w/ OT) | P17: Monthly | R17: Admin Services
A18: =_xlfn.XLOOKUP(I18,Lookup!A:A,Lookup!B:B) -> AS | B18: 27 | C18: =C17+1 -> 16 | D18: =A18&-B18&-C18 -> AS-27-16 | E18: Low Value Assets - HQ | F18: Kitchen Equipment | I18: Administrative Services | J18: Carolina C. Tenedero | K18: Carolina C. Tenedero | L18: 81123102 | M18: 52111102 | N18: Specify | Q18: e.g., plates, air fryer
A19: =_xlfn.XLOOKUP(I19,Lookup!A:A,Lookup!B:B) -> AS | B19: 27 | C19: =C18+1 -> 17 | D19: =A19&-B19&-C19 -> AS-27-17 | E19: Low Value Assets - HQ | F19: Office Equipment | I19: Administrative Services | J19: Carolina C. Tenedero | K19: Carolina C. Tenedero | L19: 81123102 | M19: 52111102 | N19: Specify | Q19: e.g., air purifier
A20: =_xlfn.XLOOKUP(I20,Lookup!A:A,Lookup!B:B) -> AS | B20: 27 | C20: =C19+1 -> 18 | D20: =A20&-B20&-C20 -> AS-27-18 | E20: LTO Registration | F20: LTO Registration | I20: Administrative Services | J20: Lino P. Arboleda | K20: Lino P. Arboleda | L20: 80123102 | M20: 61081101 | N20: No. of Vehicle, Registration Fee | O20: No. of Vehicle x Registration Fee | P20: July | R20: Admin Services
A21: =_xlfn.XLOOKUP(I21,Lookup!A:A,Lookup!B:B) -> AS | B21: 27 | C21: =C20+1 -> 19 | D21: =A21&-B21&-C21 -> AS-27-19 | E21: Office Supplies - HQ | F21: Others | I21: Administrative Services | J21: Carolina C. Tenedero | K21: Carolina C. Tenedero | L21: 81123102 | M21: 52111101 | N21: Specify
A22: =_xlfn.XLOOKUP(I22,Lookup!A:A,Lookup!B:B) -> AS | B22: 27 | C22: =C21+1 -> 20 | D22: =A22&-B22&-C22 -> AS-27-20 | E22: Office Supplies - HQ | F22: Toner/Ink | I22: Administrative Services | J22: Carolina C. Tenedero | K22: Carolina C. Tenedero | L22: 81123102 | M22: 52111101
A23: =_xlfn.XLOOKUP(I23,Lookup!A:A,Lookup!B:B) -> AS | B23: 27 | C23: =C22+1 -> 21 | D23: =A23&-B23&-C23 -> AS-27-21 | E23: Postal | F23: Postal | I23: Administrative Services | J23: Carolina C. Tenedero | K23: Carolina C. Tenedero | L23: 80123102 | M23: 61721103
A24: =_xlfn.XLOOKUP(I24,Lookup!A:A,Lookup!B:B) -> AS | B24: 27 | C24: =C23+1 -> 22 | D24: =A24&-B24&-C24 -> AS-27-22 | E24: Property Appraisal | F24: Property Appraisal | I24: Administrative Services | J24: Lino P. Arboleda | K24: Lino P. Arboleda | L24: 80123102 | M24: 61071099 | R24: Admin Services
A25: =_xlfn.XLOOKUP(I25,Lookup!A:A,Lookup!B:B) -> AS | B25: 27 | C25: =C24+1 -> 23 | D25: =A25&-B25&-C25 -> AS-27-23 | E25: Repairs & Maintenance - HQ | F25: Aircon Preventive Maintenance | I25: Administrative Services | J25: Carolina C. Tenedero | K25: Carolina C. Tenedero | L25: 81123102 | M25: 52061101
A26: =_xlfn.XLOOKUP(I26,Lookup!A:A,Lookup!B:B) -> AS | B26: 27 | C26: =C25+1 -> 24 | D26: =A26&-B26&-C26 -> AS-27-24 | E26: Repairs & Maintenance - HQ | F26: Building | I26: Administrative Services | J26: Carolina C. Tenedero | K26: Carolina C. Tenedero | L26: 81123102 | M26: 52061103 | N26: Specify
A27: =_xlfn.XLOOKUP(I27,Lookup!A:A,Lookup!B:B) -> AS | B27: 27 | C27: =C26+1 -> 25 | D27: =A27&-B27&-C27 -> AS-27-25 | E27: Repairs & Maintenance - HQ | F27: Cleaning Supplies | I27: Administrative Services | J27: Carolina C. Tenedero | K27: Carolina C. Tenedero | L27: 81123102 | M27: 52061111 | N27: Specify
A28: =_xlfn.XLOOKUP(I28,Lookup!A:A,Lookup!B:B) -> AS | B28: 27 | C28: =C27+1 -> 26 | D28: =A28&-B28&-C28 -> AS-27-26 | E28: Repairs & Maintenance - HQ | F28: Furniture, Fixture & Equipment | I28: Administrative Services | J28: Carolina C. Tenedero | K28: Carolina C. Tenedero | L28: 81123102 | M28: 52061101 | N28: Specify | Q28: e.g., carpet cleaning
A29: =_xlfn.XLOOKUP(I29,Lookup!A:A,Lookup!B:B) -> AS | B29: 27 | C29: =C28+1 -> 27 | D29: =A29&-B29&-C29 -> AS-27-27 | E29: Repairs & Maintenance - HQ | F29: Pest Control | I29: Administrative Services | J29: Carolina C. Tenedero | K29: Carolina C. Tenedero | L29: 80123102 | M29: 61061104
A30: =_xlfn.XLOOKUP(I30,Lookup!A:A,Lookup!B:B) -> AS | B30: 27 | C30: =C29+1 -> 28 | D30: =A30&-B30&-C30 -> AS-27-28 | E30: Repairs & Maintenance - HQ | F30: Vehicle | I30: Administrative Services | J30: Carolina C. Tenedero | K30: Carolina C. Tenedero | L30: 80123102 | M30: 61061104 | N30: No. of Vehicle, Allowed Limit of R&M per Month | O30: No. of Vehicle x Allowed Limit of R&M per Month | P30: Monthly
A31: =_xlfn.XLOOKUP(I31,Lookup!A:A,Lookup!B:B) -> AS | B31: 27 | C31: =C30+1 -> 29 | D31: =A31&-B31&-C31 -> AS-27-29 | E31: Security Services | F31: Security Services | I31: Administrative Services | J31: Carolina C. Tenedero | K31: Carolina C. Tenedero | L31: 81123102 | M31: 52041401 | N31: Headcount, Rate per Month (w/ OT) | O31: Headcount x Rate per Month (w/ OT) | P31: Monthly | R31: Admin Services
A32: =_xlfn.XLOOKUP(I32,Lookup!A:A,Lookup!B:B) -> AS | B32: 27 | C32: =C31+1 -> 30 | D32: =A32&-B32&-C32 -> AS-27-30 | E32: Transportation | F32: Parking Fees | I32: Administrative Services | J32: Carolina C. Tenedero | K32: Carolina C. Tenedero | L32: 81123102 | M32: 52081101 | R32: Admin Services
A33: =_xlfn.XLOOKUP(I33,Lookup!A:A,Lookup!B:B) -> AS | B33: 27 | C33: =C32+1 -> 31 | D33: =A33&-B33&-C33 -> AS-27-31 | E33: Transportation | F33: Toll Fees/RFID | I33: Administrative Services | J33: Carolina C. Tenedero | K33: Carolina C. Tenedero | L33: 81123102 | M33: 52081101 | R33: Admin Services
A34: =_xlfn.XLOOKUP(I34,Lookup!A:A,Lookup!B:B) -> AS | B34: 27 | C34: =C33+1 -> 32 | D34: =A34&-B34&-C34 -> AS-27-32 | E34: Transportation | F34: Vehicle Supplies | I34: Administrative Services | J34: Carolina C. Tenedero | K34: Carolina C. Tenedero | L34: 80123102 | M34: 61081101
A35: =_xlfn.XLOOKUP(I35,Lookup!A:A,Lookup!B:B) -> AS | B35: 27 | C35: =C34+1 -> 33 | D35: =A35&-B35&-C35 -> AS-27-33 | E35: Vehicle Insurance | F35: Vehicle Insurance | I35: Administrative Services | J35: Lino P. Arboleda | K35: Lino P. Arboleda | L35: 80123102 | M35: 61061104 | N35: No. of Vehicle, Allowed Limit of Insurance Anually | O35: No. of Vehicle x Allowed Limit of Insurance Anually | P35: July | R35: Admin Services
A36: =_xlfn.XLOOKUP(I36,Lookup!A:A,Lookup!B:B) -> BCA | B36: 27 | C36: =C35+1 -> 34 | D36: =A36&-B36&-C36 -> BCA-27-34 | E36: Dues and Fees | F36: Budget Reserve | I36: Budget, Controls & Analysis | J36: Princess Vera P. Jumalon | K36: Princess Vera P. Jumalon | L36: 80134103 | M36: 61711101
A37: =_xlfn.XLOOKUP(I37,Lookup!A:A,Lookup!B:B) -> BCA | B37: 27 | C37: =C36+1 -> 35 | D37: =A37&-B37&-C37 -> BCA-27-35 | E37: MTS | F37: MTS | I37: Budget, Controls & Analysis | J37: Princess Vera P. Jumalon | K37: Princess Vera P. Jumalon | L37: 80134103 | M37: 61901109
A38: =_xlfn.XLOOKUP(I38,Lookup!A:A,Lookup!B:B) -> BCA | B38: 27 | C38: =C37+1 -> 36 | D38: =A38&-B38&-C38 -> BCA-27-36 | E38: MTS | F38: MTS Recovery | I38: Budget, Controls & Analysis | J38: Princess Vera P. Jumalon | K38: Princess Vera P. Jumalon | L38: 81123102 | M38: 52041502
A39: =_xlfn.XLOOKUP(I39,Lookup!A:A,Lookup!B:B) -> BCA | B39: 27 | C39: =C38+1 -> 37 | D39: =A39&-B39&-C39 -> BCA-27-37 | E39: MTS | F39: MTS Recovery | I39: Budget, Controls & Analysis | J39: Princess Vera P. Jumalon | K39: Princess Vera P. Jumalon | L39: 80123102 | M39: 61961302
A40: =_xlfn.XLOOKUP(I40,Lookup!A:A,Lookup!B:B) -> BCA | B40: 27 | C40: =C39+1 -> 38 | D40: =A40&-B40&-C40 -> BCA-27-38 | E40: Performance Bonus | F40: Performance Bonus | G40: OCLP | I40: Budget, Controls & Analysis | J40: Princess Vera P. Jumalon | K40: Princess Vera P. Jumalon | L40: 80111101 | M40: 61021317
...

Sheet Lookup
A2: Administrative Services | B2: AS
A3: Corporate Finance | B3: CF
A4: External Affairs | B4: EA
A5: Human Resources | B5: HR
A6: Information System & Information Technology | B6: IT
A7: Legal | B7: LG
A8: Office of the CFO | B8: CF
A9: Tax | B9: TX
A10: Budget, Controls & Analysis | B10: BCA
A11: Corporate Marketing | B11: CM
A12: OMD Operations | B12: OM
A13: Procurement | B13: PR
A14: TECHNICAL SERVICES | B14: TS

Sheet Sheet2
A1: Department | B1: Admin
A2: GL number | B2: GL description | C2: Rule | D2: Full year 2025 | E2: YTD September 2026 | F2: October-December 2026 Forecast | G2: Full Year 2026 | H2: Average Monthly 2026 | I2: Full year 2027
A3: 52041499 | B3: Admin Staff - Driver/Messenger | C3: Headcount, Rate per day, no of days
A4: 52041499 | B4: Admin Staff - Driver/Messenger | C4: Headcount, Rate per day, no of days
A5: 52081103 | B5: Drivers' Meal Allowance | C5: Headcount, fixed rate
A6: 61711101 | B6: Dues and Fees - Others | C6: Dropdown selection: membership (specify), others (specify)
A7: 61041101 | B7: Electricity & Water | C7: Based on PY average, consider increase in meralco etc
A8: 52119101 | B8: Fuel & Lubricants - Messenger | C8: No of trips per day, no of days, no of messenger, based on PY average, consider increase in fuel
A9: 61111201 | B9: Fuel & Lubricants - Shell Fleet | C9: Based on PY average, consider increase in fuel
A10: 52041405 | B10: Janitorial | C10: Headcount, Rate per day, no of days
A11: 52111102 | B11: Low Value Assets
A12: 61081101 | B12: LTO Registration
A13: 52951101 | B13: Mobile Phone
A14: 52111101 | B14: Office Supplies - Toner
A15: 52081101 | B15: Parking Fees
A16: 61071099 | B16: Property Valuation
A17: 61061104 | B17: Repairs & Maintenance - Vehicle
A18: 52061103 | B18: Repairs & Maintenance - Building
A19: 52061101 | B19: Repairs & Maintenance - Furniture, Fixture & Equipment
A20: 52061111 | B20: Repairs & Maintenance - Supplies
A21: 52041401 | B21: Security | C21: Headcount, Rate per day, no of days
A22: 52081101 | B22: Parking Fees
A23: 52081101 | B23: Parking Fees
A24: 61721101 | B24: Trunk Line/Direct Line/Land Line
A25: 61061104 | B25: Repairs & Maintenance - Vehicle
